Workbook

Sheet Sheet1
A1: 언어별계정항목등록
A2: 항목명 | B2: 참조값 | C2: 한국어 | D2: English | E2: 日本語 | F2: 简体中文 | G2: 繁體中文 | H2: Tiếng việt
A3: 1000000 -1000000 Tài sản ngắn hạn | B3: 1000000 | C3: 1000000 - 단기 자산 (1000000) | D3: 1000000 - 1000000 Current assets | I3: =VLOOKUP(B3,[1]원본!$B$3:$B$689,1,FALSE) -> 1000000
A4: 1110000 -Tiền mặt | B4: 1110000 | C4: 1110000 - 현금 | D4: 1110000 - Cash in hand | I4: =VLOOKUP(B4,[1]원본!$B$3:$B$689,1,FALSE) -> 1110000
A5: 1111000 -Tiền Việt Nam | B5: 1111000 | C5: 1111000 - 현금 | D5: 1111000 - Vietnam dong | I5: =VLOOKUP(B5,[1]원본!$B$3:$B$689,1,FALSE) -> 1111000
A6: 1112000 -Ngoại tệ | B6: 1112000 | C6: 1112000 - 외화 현금 | D6: 1112000 - Foreign currency | I6: =VLOOKUP(B6,[1]원본!$B$3:$B$689,1,FALSE) -> 1112000
A7: 1113000 -Vàng tiền tệ | B7: 1113000 | C7: 1113000 - 통화성 금 | D7: 1113000 - Monetary gold | I7: =VLOOKUP(B7,[1]원본!$B$3:$B$689,1,FALSE) -> 1113000
A8: 1120000 -Tiền gửi ngân hàng | B8: 1120000 | C8: 1120000 - 은행 예금 | D8: 1120000 - Cash in bank | I8: =VLOOKUP(B8,[1]원본!$B$3:$B$689,1,FALSE) -> 1120000
A9: 1121000 -Tiền Việt Nam | B9: 1121000 | C9: 1121000 - 베트남 동 예금 | D9: 1121000 - Vietnam dong | I9: =VLOOKUP(B9,[1]원본!$B$3:$B$689,1,FALSE) -> 1121000
A10: 1121100 -Tiền Việt Nam(Wooribank) | B10: 1121100 | C10: 1121100 - 보통예금(Woori Bank) | D10: 1121100 - Vietnam dong- -Wooribank-100100203225 | I10: =VLOOKUP(B10,[1]원본!$B$3:$B$689,1,FALSE) -> 1121100
A11: 1121200 -Tiền Việt Nam(ANZ) | B11: 1121200 | C11: 1121200 - 보통예금(ANZ-9833818) | D11: 1121200 - Vietnam dong-ANZ-9833818 | I11: =VLOOKUP(B11,[1]원본!$B$3:$B$689,1,FALSE) -> 1121200
A12: 1121300 -Tiền Việt Nam(Vietcom Bank) | B12: 1121300 | C12: 1121300 - 보통예금(Vietcom Bank) | D12: 1121300 - Vietnam dong-VIETCOMBANK- 5858686688 | I12: =VLOOKUP(B12,[1]원본!$B$3:$B$689,1,FALSE) -> 1121300
A13: 1121400 -Tiền Việt Nam(BIDV Bank) | B13: 1121400 | C13: 1121400 - 보통예금(BIDV Bank) | D13: 1121400 - Vietnam dong-BIDV-8682688888 | I13: =VLOOKUP(B13,[1]원본!$B$3:$B$689,1,FALSE) -> 1121400
A14: 1121500 -Tiền Việt Nam(MSB Bank) | B14: 1121500 | I14: =VLOOKUP(B14,[1]원본!$B$3:$B$689,1,FALSE) -> #N/A
A15: 1121800 -Tiền gửi ngân hàng khác | B15: 1121800 | C15: 1121800 - 보통예금-기타 | D15: 1121800 - Other bank deposits | I15: =VLOOKUP(B15,[1]원본!$B$3:$B$689,1,FALSE) -> 1121800
A16: 1122000 -Ngoại tệ | B16: 1122000 | C16: 1122000 - 보통예금-외화 | D16: 1122000 - Foreign currency | I16: =VLOOKUP(B16,[1]원본!$B$3:$B$689,1,FALSE) -> 1122000
A17: 1122100 -Ngoại tệ(Wooribank) - 101100001876 | B17: 1122100 | C17: 1122100 - 외화예금(Wooribank) - 101100001876 | D17: 1122100 - Foreign currency- Wooribank-101100001876- DICA-USD | I17: =VLOOKUP(B17,[1]원본!$B$3:$B$689,1,FALSE) -> 1122100
A18: 1122200 -Ngoại tệ(Wooribank) - 100100203203 | B18: 1122200 | C18: 1122200 - 외화예금(Wooribank) | D18: 1122200 - Foreign currency-Wooribank- 100100203203- USD | I18: =VLOOKUP(B18,[1]원본!$B$3:$B$689,1,FALSE) -> 1122200
A19: 1122300 -Ngoại tệ(ANZ) | B19: 1122300 | C19: 1122300 - 외화예금(ANZ) | D19: 1122300 - Foreign currency- ANZ-9839311- USD | I19: =VLOOKUP(B19,[1]원본!$B$3:$B$689,1,FALSE) -> 1122300
A20: 1122400 -Ngoại tệ(VIETCOMBANK) -5959686688 (USD) | B20: 1122400 | C20: 1122400 - 외화예금(Vietcombank) | I20: =VLOOKUP(B20,[1]원본!$B$3:$B$689,1,FALSE) -> 1122400
A21: 1123000 -Vàng tiền tệ | B21: 1123000 | C21: 1123000 - 통화성 금 | D21: 1123000 - Monetary gold | I21: =VLOOKUP(B21,[1]원본!$B$3:$B$689,1,FALSE) -> 1123000
A22: 1130000 -Tiền đang chuyển | B22: 1130000 | C22: 1130000 - 이체 중인 현금 | D22: 1130000 - Cash in transit | I22: =VLOOKUP(B22,[1]원본!$B$3:$B$689,1,FALSE) -> 1130000
A23: 1131000 -Tiền Việt Nam | B23: 1131000 | C23: 1131000 - 베트남 동 현금 | D23: 1131000 - Vietnam dong | I23: =VLOOKUP(B23,[1]원본!$B$3:$B$689,1,FALSE) -> 1131000
A24: 1132000 -Ngoại tệ | B24: 1132000 | C24: 1132000 - 외화 현금 | D24: 1132000 - Foreign currency | I24: =VLOOKUP(B24,[1]원본!$B$3:$B$689,1,FALSE) -> 1132000
A25: 1210000 -Chứng khoán kinh doanh | B25: 1210000 | C25: 1210000 - 단기 매매증권 | D25: 1210000 - Securities trading | I25: =VLOOKUP(B25,[1]원본!$B$3:$B$689,1,FALSE) -> 1210000
A26: 1211000 -Cổ phiếu | B26: 1211000 | C26: 1211000 - 주식 | D26: 1211000 - Stocks | I26: =VLOOKUP(B26,[1]원본!$B$3:$B$689,1,FALSE) -> 1211000
A27: 1212000 -Trái phiếu | B27: 1212000 | C27: 1212000 - 채권 | D27: 1212000 - Bonds | I27: =VLOOKUP(B27,[1]원본!$B$3:$B$689,1,FALSE) -> 1212000
A28: 1218000 -Chứng khoán và công cụ tài chính khác | B28: 1218000 | C28: 1218000 - 기타 유가증권 및 금융상품 | D28: 1218000 - Securities and other financial instruments | I28: =VLOOKUP(B28,[1]원본!$B$3:$B$689,1,FALSE) -> 1218000
A29: 1280000 -Đầu tư nắm giữ đến ngày đáo hạn | B29: 1280000 | C29: 1280000 - 만기보유 투자 | D29: 1280000 - Other short - term investment | I29: =VLOOKUP(B29,[1]원본!$B$3:$B$689,1,FALSE) -> 1280000
A30: 1281000 -Tiền gửi có kỳ hạn | B30: 1281000 | C30: 1281000 - 정기예금 | D30: 1281000 - Term deposits | I30: =VLOOKUP(B30,[1]원본!$B$3:$B$689,1,FALSE) -> 1281000
A31: 1281100 -Tiền gửi có kỳ hạn =< 3 tháng | B31: 1281100 | C31: 1281100 - 3개월 이하 정기예금 | D31: 1281100 - Term deposits - 3 months | I31: =VLOOKUP(B31,[1]원본!$B$3:$B$689,1,FALSE) -> 1281100
A32: 1281200 -Tiền gửi có kỳ hạn > 3 tháng | B32: 1281200 | C32: 1281200 - 3개월 초과 정기예금 | D32: 1281200 - Term deposits - over 3 months | I32: =VLOOKUP(B32,[1]원본!$B$3:$B$689,1,FALSE) -> 1281200
... A673: 9110000 -Xác định kết quả kinh doanh | B673: 9110000 | C673: 9110000 - 당기손익계산 | D673: 9110000 - Evaluation of business results | I673: =VLOOKUP(B673,[1]원본!$B$3:$B$689,1,FALSE) -> 9110000
A674: 9211100-Kết chuyển nhập kho khác NVL chính(1521) | B674: 9211100 | C674: 9211100 - 타계정에서 원재료비대체액 | I674: =VLOOKUP(B674,[1]원본!$B$3:$B$689,1,FALSE) -> 9211100
A675: 9211200-Kết chuyển nhập kho khác NVL phụ(1522) | B675: 9211200 | C675: 9211200 - 타계정에서 부재료비대체액 | I675: =VLOOKUP(B675,[1]원본!$B$3:$B$689,1,FALSE) -> 9211200
A676: 9211300-Kết chuyển nhập kho khác TP | B676: 9211300 | C676: 9211300 - 기타 제품 입고 대체 | I676: =VLOOKUP(B676,[1]원본!$B$3:$B$689,1,FALSE) -> 9211300
A677: 9211400-Kết chuyển nhập kho khác HH | B677: 9211400 | C677: 9211400 - 기타 상품 입고 대체 | I677: =VLOOKUP(B677,[1]원본!$B$3:$B$689,1,FALSE) -> 9211400
A678: 9211500-Kết chuyển từ tài khoản khác ( Nợ TK chi phí dở dang) | B678: 9211500 | C678: 9211500 - 타계정에서 재공품대체액 | I678: =VLOOKUP(B678,[1]원본!$B$3:$B$689,1,FALSE) -> 9211500
A679: 9211600-Kết chuyển nhập kho khác (Bán thành phẩm) | B679: 9211600 | C679: 9211600 - 기타 입고 대체 전표(반제품) | I679: =VLOOKUP(B679,[1]원본!$B$3:$B$689,1,FALSE) -> 9211600
A680: 9211700-Kết chuyển nhập kho khác CCDC | B680: 9211700 | C680: 9211700 - 기타 공구 기구 입고 대체 | I680: =VLOOKUP(B680,[1]원본!$B$3:$B$689,1,FALSE) -> 9211700
...
