Workbook

Sheet 재공품 (WIP)_생산실적
X1: 열고 닫는 기능 추가 필요 (좌측으로) | AH1: 열고 닫는 기능 추가 필요 (좌측으로) | AY1: 열고 닫는 기능 추가 필요 (좌측으로)
B2: 모델 Model | C2: 구분 Division | D2: 기초 / BOH | R2: 입고 / INPUT | S2: 기타입고 / Other Input (6=1+2+3+4+5) | Y2: 출고 / OUTPUT | Z2: 기타출고 / Other Output | AJ2: LOSS (SCRAP) | AM2: 재고 / EOH
D3: 1 | F3: 2 | H3: 3=1+2 | J3: 4 | L3: 5 | N3: 6=4+5 | P3: 7=1+2+4+5 | R3: 1 | S3: 1 | T3: 2 | U3: 3 | V3: 4 | W3: 5 | X3: 6 | Y3: 1 | Z3: 1 | AB3: 2 | AD3: 3 | AF3: 4 | AH3: 5 | AM3: 1 | AO3: 2 | AQ3: 3 | AS3: 4 | AU3: 5 (1+3) | AW3: 6 (2+4) | AY3: TOTAL_EOH (MES) 7=5+6
D4: LINE_WIP | F4: LINE_FGS | H4: BOH A_LEVEL SUB TOTAL | J4: B_LEVEL_WIP | L4: B_LEVEL_FGS | N4: BOH B_LEVEL SUB TOTAL | P4: T_BOH | R4: USC_INPUT (C) | S4: CODE 변경 | T4: Re-Sorting (재검사) | U4: Re-work (SI검사) | V4: 반제품 입고 | W4: 기타 | X4: 기타입고 | Y4: OUTPUT_A (C) | Z4: CODE 변경 | AB4: 반제품 출고 (유상) | AD4: 반제품 출고 (무상) | AF4: 기타 | AH4: 기타출고 (5=1+2+3+4) | AM4: LINE_WIP (A) | AO4: LINE_FGs (A) | AQ4: B_LEVEL WIP (A) | AS4: B_LEVEL FGs | AU4: T_EOH WIP | AW4: T_EOH FGs
D5: PFL전 50% | E5: PFL후 90% | F5: PFL전 50% | G5: PFL후 90% | H5: PFL전 50% | I5: PFL후 90% | J5: PFL전 50% | K5: PFL후 90% | L5: PFL전 50% | M5: PFL후 90% | N5: PFL전 50% | O5: PFL후 90% | P5: PFL전 50% | Q5: PFL후 90% | Z5: PFL전 50% | AA5: PFL후 90% | AB5: PFL전 50% | AC5: PFL후 90% | AD5: PFL전 50% | AE5: PFL후 90% | AF5: PFL전 50% | AG5: PFL후 90% | AH5: PFL전 50% | AI5: PFL후 90% | AJ5: PFL전 50% | AK5: PFL후 90% | AL5: 합계 | AM5: PFL전 50% | AN5: PFL후 90% | AO5: PFL전 50% | AP5: PFL후 90% | AQ5: PFL전 50% | AR5: PFL후 90% | AS5: PFL전 50% | AT5: PFL후 90% | AU5: PFL전 50% | AV5: PFL후 90% | AW5: PFL전 50% | AX5: PFL후 90% | AY5: PFL전 50% | AZ5: PFL후 90%
B6: 7075P | C6: MP | D6: 0 | E6: 0 | F6: 0 | G6: 0 | H6: =D6+F6 -> 0 | I6: =E6+G6 -> 0 | J6: 6 | K6: 7 | L6: 0 | M6: 0 | N6: =J6+L6 -> 6 | O6: =K6+M6 -> 7 | P6: =H6+N6 -> 6 | Q6: =I6+O6 -> 7 | R6: 0 | S6: 0 | T6: 0 | U6: 0 | V6: 0 | W6: 0 | X6: =SUM(S6:W6) -> 0 | Y6: 0 | Z6: 0 | AA6: 0 | AB6: 0 | AC6: 0 | AD6: 0 | AE6: 0 | AF6: 0 | AG6: 0 | AH6: =Z6+AB6+AD6+AF6 -> 0 | AI6: =AA6+AC6+AE6+AG6 -> 0 | AJ6: 0 | AK6: 0 | AL6: =AJ6+AK6 -> 0 | AM6: 0 | AN6: 0 | AO6: 0 | AP6: 0 | AQ6: 6 | AR6: 7 | AS6: 0 | AT6: 0 | AU6: =AM6+AQ6 -> 6 | AV6: =AN6+AR6 -> 7 | AW6: =AO6+AS6 -> 0 | AX6: =AP6+AT6 -> 0 | AY6: =AU6+AW6 -> 6 | AZ6: =AV6+AX6 -> 7
B7: 712TP | C7: MP | D7: 0 | E7: 0 | F7: 0 | G7: 0 | H7: =D7+F7 -> 0 | I7: =E7+G7 -> 0 | J7: 173 | K7: 11 | L7: 0 | M7: 0 | N7: =J7+L7 -> 173 | O7: =K7+M7 -> 11 | P7: =H7+N7 -> 173 | Q7: =I7+O7 -> 11 | R7: 0 | S7: 0 | T7: 0 | U7: 0 | V7: 0 | W7: 0 | X7: =SUM(S7:W7) -> 0 | Y7: 0 | Z7: 0 | AA7: 0 | AB7: 0 | AC7: 0 | AD7: 0 | AE7: 0 | AF7: 0 | AG7: 0 | AH7: =Z7+AB7+AD7+AF7 -> 0 | AI7: =AA7+AC7+AE7+AG7 -> 0 | AJ7: 0 | AK7: 0 | AL7: =AJ7+AK7 -> 0 | AM7: 0 | AN7: 0 | AO7: 0 | AP7: 0 | AQ7: 173 | AR7: 11 | AS7: 0 | AT7: 0 | AU7: =AM7+AQ7 -> 173 | AV7: =AN7+AR7 -> 11 | AW7: =AO7+AS7 -> 0 | AX7: =AP7+AT7 -> 0 | AY7: =AU7+AW7 -> 173 | AZ7: =AV7+AX7 -> 11
B8: 716AP | C8: MP | D8: 30912 | E8: 17821 | F8: 0 | G8: 15621 | H8: =D8+F8 -> 30912 | I8: =E8+G8 -> 33442 | J8: 2246 | K8: 292 | L8: 0 | M8: 23 | N8: =J8+L8 -> 2246 | O8: =K8+M8 -> 315 | P8: =H8+N8 -> 33158 | Q8: =I8+O8 -> 33757 | R8: 499392 | S8: 0 | T8: 260558 | U8: 9765 | V8: 0 | W8: 0 | X8: =SUM(S8:W8) -> 270323 | Y8: 757675 | Z8: 0 | AA8: 0 | AB8: 0 | AC8: 10 | AD8: 5 | AE8: 0 | AF8: 0 | AG8: 0 | AH8: =Z8+AB8+AD8+AF8 -> 5 | AI8: =AA8+AC8+AE8+AG8 -> 10 | AJ8: 10901 | AK8: 8366 | AL8: =AJ8+AK8 -> 19267 | AM8: 33958 | AN8: 13774 | AO8: 0 | AP8: 8103 | AQ8: 3283 | AR8: 502 | AS8: 0 | AT8: 53 | AU8: =AM8+AQ8 -> 37241 | AV8: =AN8+AR8 -> 14276 | AW8: =AO8+AS8 -> 0 | AX8: =AP8+AT8 -> 8156 | AY8: =AU8+AW8 -> 37241 | AZ8: =AV8+AX8 -> 22432
B9: 716BD | C9: R&D | D9: 0 | E9: 0 | F9: 0 | G9: 0 | H9: =D9+F9 -> 0 | I9: =E9+G9 -> 0 | J9: 69 | K9: 4 | L9: 0 | M9: 0 | N9: =J9+L9 -> 69 | O9: =K9+M9 -> 4 | P9: =H9+N9 -> 69 | Q9: =I9+O9 -> 4 | R9: 0 | S9: 0 | T9: 0 | U9: 0 | V9: 0 | W9: 0 | X9: =SUM(S9:W9) -> 0 | Y9: 0 | Z9: 0 | AA9: 0 | AB9: 0 | AC9: 0 | AD9: 0 | AE9: 0 | AF9: 0 | AG9: 0 | AH9: =Z9+AB9+AD9+AF9 -> 0 | AI9: =AA9+AC9+AE9+AG9 -> 0 | AJ9: 0 | AK9: 0 | AL9: =AJ9+AK9 -> 0 | AM9: 0 | AN9: 0 | AO9: 0 | AP9: 0 | AQ9: 69 | AR9: 4 | AS9: 0 | AT9: 0 | AU9: =AM9+AQ9 -> 69 | AV9: =AN9+AR9 -> 4 | AW9: =AO9+AS9 -> 0 | AX9: =AP9+AT9 -> 0 | AY9: =AU9+AW9 -> 69 | AZ9: =AV9+AX9 -> 4
B10: 716CD | C10: R&D | D10: 0 | E10: 0 | F10: 0 | G10: 0 | H10: =D10+F10 -> 0 | I10: =E10+G10 -> 0 | J10: 0 | K10: 1 | L10: 0 | M10: 0 | N10: =J10+L10 -> 0 | O10: =K10+M10 -> 1 | P10: =H10+N10 -> 0 | Q10: =I10+O10 -> 1 | R10: 0 | S10: 0 | T10: 0 | U10: 0 | V10: 0 | W10: 0 | X10: =SUM(S10:W10) -> 0 | Y10: 0 | Z10: 0 | AA10: 0 | AB10: 0 | AC10: 0 | AD10: 0 | AE10: 0 | AF10: 0 | AG10: 0 | AH10: =Z10+AB10+AD10+AF10 -> 0 | AI10: =AA10+AC10+AE10+AG10 -> 0 | AJ10: 0 | AK10: 0 | AL10: =AJ10+AK10 -> 0 | AM10: 0 | AN10: 0 | AO10: 0 | AP10: 0 | AQ10: 0 | AR10: 1 | AS10: 0 | AT10: 0 | AU10: =AM10+AQ10 -> 0 | AV10: =AN10+AR10 -> 1 | AW10: =AO10+AS10 -> 0 | AX10: =AP10+AT10 -> 0 | AY10: =AU10+AW10 -> 0 | AZ10: =AV10+AX10 -> 1
B11: 716DD | C11: R&D | D11: 0 | E11: 0 | F11: 0 | G11: 0 | H11: =D11+F11 -> 0 | I11: =E11+G11 -> 0 | J11: 328 | K11: 2161 | L11: 0 | M11: 144 | N11: =J11+L11 -> 328 | O11: =K11+M11 -> 2305 | P11: =H11+N11 -> 328 | Q11: =I11+O11 -> 2305 | R11: 0 | S11: 0 | T11: 0 | U11: 0 | V11: 0 | W11: 0 | X11: =SUM(S11:W11) -> 0 | Y11: 0 | Z11: 0 | AA11: 0 | AB11: 0 | AC11: 0 | AD11: 0 | AE11: 0 | AF11: 0 | AG11: 0 | AH11: =Z11+AB11+AD11+AF11 -> 0 | AI11: =AA11+AC11+AE11+AG11 -> 0 | AJ11: 0 | AK11: 2295 | AL11: =AJ11+AK11 -> 2295 | AM11: 0 | AN11: 0 | AO11: 0 | AP11: 0 | AQ11: 328 | AR11: 10 | AS11: 0 | AT11: 0 | AU11: =AM11+AQ11 -> 328 | AV11: =AN11+AR11 -> 10 | AW11: =AO11+AS11 -> 0 | AX11: =AP11+AT11 -> 0 | AY11: =AU11+AW11 -> 328 | AZ11: =AV11+AX11 -> 10
B12: 716DTT | C12: R&D | D12: 0 | E12: 0 | F12: 0 | G12: 0 | H12: =D12+F12 -> 0 | I12: =E12+G12 -> 0 | J12: 320 | K12: 0 | L12: 0 | M12: 0 | N12: =J12+L12 -> 320 | O12: =K12+M12 -> 0 | P12: =H12+N12 -> 320 | Q12: =I12+O12 -> 0 | R12: 16 | S12: 0 | T12: 0 | U12: 0 | V12: 0 | W12: 0 | X12: =SUM(S12:W12) -> 0 | Y12: 0 | Z12: 0 | AA12: 0 | AB12: 0 | AC12: 0 | AD12: 300 | AE12: 0 | AF12: 0 | AG12: 0 | AH12: =Z12+AB12+AD12+AF12 -> 300 | AI12: =AA12+AC12+AE12+AG12 -> 0 | AJ12: 36 | AK12: 0 | AL12: =AJ12+AK12 -> 36 | AM12: 0 | AN12: 0 | AO12: 0 | AP12: 0 | AQ12: 0 | AR12: 0 | AS12: 0 | AT12: 0 | AU12: =AM12+AQ12 -> 0 | AV12: =AN12+AR12 -> 0 | AW12: =AO12+AS12 -> 0 | AX12: =AP12+AT12 -> 0 | AY12: =AU12+AW12 -> 0 | AZ12: =AV12+AX12 -> 0
B13: 716ED | C13: R&D | D13: 0 | E13: 0 | F13: 0 | G13: 0 | H13: =D13+F13 -> 0 | I13: =E13+G13 -> 0 | J13: 31 | K13: 1 | L13: 0 | M13: 0 | N13: =J13+L13 -> 31 | O13: =K13+M13 -> 1 | P13: =H13+N13 -> 31 | Q13: =I13+O13 -> 1 | R13: 0 | S13: 0 | T13: 0 | U13: 0 | V13: 0 | W13: 0 | X13: =SUM(S13:W13) -> 0 | Y13: 0 | Z13: 0 | AA13: 0 | AB13: 0 | AC13: 0 | AD13: 0 | AE13: 0 | AF13: 0 | AG13: 0 | AH13: =Z13+AB13+AD13+AF13 -> 0 | AI13: =AA13+AC13+AE13+AG13 -> 0 | AJ13: 0 | AK13: 0 | AL13: =AJ13+AK13 -> 0 | AM13: 0 | AN13: 0 | AO13: 0 | AP13: 0 | AQ13: 31 | AR13: 1 | AS13: 0 | AT13: 0 | AU13: =AM13+AQ13 -> 31 | AV13: =AN13+AR13 -> 1 | AW13: =AO13+AS13 -> 0 | AX13: =AP13+AT13 -> 0 | AY13: =AU13+AW13 -> 31 | AZ13: =AV13+AX13 -> 1
B14: 716ETT | C14: R&D | D14: 0 | E14: 0 | F14: 0 | G14: 0 | H14: =D14+F14 -> 0 | I14: =E14+G14 -> 0 | J14: 576 | K14: 0 | L14: 0 | M14: 0 | N14: =J14+L14 -> 576 | O14: =K14+M14 -> 0 | P14: =H14+N14 -> 576 | Q14: =I14+O14 -> 0 | R14: 256 | S14: 0 | T14: 0 | U14: 0 | V14: 0 | W14: 0 | X14: =SUM(S14:W14) -> 0 | Y14: 0 | Z14: 0 | AA14: 0 | AB14: 350 | AC14: 0 | AD14: 0 | AE14: 0 | AF14: 0 | AG14: 0 | AH14: =Z14+AB14+AD14+AF14 -> 350 | AI14: =AA14+AC14+AE14+AG14 -> 0 | AJ14: 418 | AK14: 0 | AL14: =AJ14+AK14 -> 418 | AM14: 0 | AN14: 0 | AO14: 0 | AP14: 0 | AQ14: 64 | AR14: 0 | AS14: 0 | AT14: 0 | AU14: =AM14+AQ14 -> 64 | AV14: =AN14+AR14 -> 0 | AW14: =AO14+AS14 -> 0 | AX14: =AP14+AT14 -> 0 | AY14: =AU14+AW14 -> 64 | AZ14: =AV14+AX14 -> 0
B15: 716FD | C15: R&D | D15: 0 | E15: 0 | F15: 0 | G15: 0 | H15: =D15+F15 -> 0 | I15: =E15+G15 -> 0 | J15: 67 | K15: 1 | L15: 0 | M15: 0 | N15: =J15+L15 -> 67 | O15: =K15+M15 -> 1 | P15: =H15+N15 -> 67 | Q15: =I15+O15 -> 1 | R15: 0 | S15: 0 | T15: 0 | U15: 0 | V15: 0 | W15: 0 | X15: =SUM(S15:W15) -> 0 | Y15: 0 | Z15: 0 | AA15: 0 | AB15: 0 | AC15: 0 | AD15: 0 | AE15: 0 | AF15: 0 | AG15: 0 | AH15: =Z15+AB15+AD15+AF15 -> 0 | AI15: =AA15+AC15+AE15+AG15 -> 0 | AJ15: 0 | AK15: 0 | AL15: =AJ15+AK15 -> 0 | AM15: 0 | AN15: 0 | AO15: 0 | AP15: 0 | AQ15: 67 | AR15: 1 | AS15: 0 | AT15: 0 | AU15: =AM15+AQ15 -> 67 | AV15: =AN15+AR15 -> 1 | AW15: =AO15+AS15 -> 0 | AX15: =AP15+AT15 -> 0 | AY15: =AU15+AW15 -> 67 | AZ15: =AV15+AX15 -> 1
B16: 716GD | C16: R&D | D16: 0 | E16: 0 | F16: 0 | G16: 0 | H16: =D16+F16 -> 0 | I16: =E16+G16 -> 0 | J16: 2 | K16: 1 | L16: 0 | M16: 0 | N16: =J16+L16 -> 2 | O16: =K16+M16 -> 1 | P16: =H16+N16 -> 2 | Q16: =I16+O16 -> 1 | R16: 0 | S16: 0 | T16: 0 | U16: 0 | V16: 0 | W16: 0 | X16: =SUM(S16:W16) -> 0 | Y16: 0 | Z16: 0 | AA16: 0 | AB16: 0 | AC16: 0 | AD16: 0 | AE16: 0 | AF16: 0 | AG16: 0 | AH16: =Z16+AB16+AD16+AF16 -> 0 | AI16: =AA16+AC16+AE16+AG16 -> 0 | AJ16: 0 | AK16: 0 | AL16: =AJ16+AK16 -> 0 | AM16: 0 | AN16: 0 | AO16: 0 | AP16: 0 | AQ16: 2 | AR16: 1 | AS16: 0 | AT16: 0 | AU16: =AM16+AQ16 -> 2 | AV16: =AN16+AR16 -> 1 | AW16: =AO16+AS16 -> 0 | AX16: =AP16+AT16 -> 0 | AY16: =AU16+AW16 -> 2 | AZ16: =AV16+AX16 -> 1
B17: 716JD | C17: R&D | D17: 0 | E17: 0 | F17: 0 | G17: 0 | H17: =D17+F17 -> 0 | I17: =E17+G17 -> 0 | J17: 15 | K17: 1 | L17: 0 | M17: 0 | N17: =J17+L17 -> 15 | O17: =K17+M17 -> 1 | P17: =H17+N17 -> 15 | Q17: =I17+O17 -> 1 | R17: 0 | S17: 0 | T17: 0 | U17: 0 | V17: 0 | W17: 0 | X17: =SUM(S17:W17) -> 0 | Y17: 0 | Z17: 0 | AA17: 0 | AB17: 0 | AC17: 0 | AD17: 0 | AE17: 0 | AF17: 0 | AG17: 0 | AH17: =Z17+AB17+AD17+AF17 -> 0 | AI17: =AA17+AC17+AE17+AG17 -> 0 | AJ17: 0 | AK17: 0 | AL17: =AJ17+AK17 -> 0 | AM17: 0 | AN17: 0 | AO17: 0 | AP17: 0 | AQ17: 15 | AR17: 1 | AS17: 0 | AT17: 0 | AU17: =AM17+AQ17 -> 15 | AV17: =AN17+AR17 -> 1 | AW17: =AO17+AS17 -> 0 | AX17: =AP17+AT17 -> 0 | AY17: =AU17+AW17 -> 15 | AZ17: =AV17+AX17 -> 1
... B77: 8191D | C77: R&D | D77: 0 | E77: 0 | F77: 0 | G77: 0 | H77: =D77+F77 -> 0 | I77: =E77+G77 -> 0 | J77: 30 | K77: 1 | L77: 0 | M77: 0 | N77: =J77+L77 -> 30 | O77: =K77+M77 -> 1 | P77: =H77+N77 -> 30 | Q77: =I77+O77 -> 1 | R77: 0 | S77: 0 | T77: 0 | U77: 0 | V77: 0 | W77: 0 | X77: =SUM(S77:W77) -> 0 | Y77: 0 | Z77: 0 | AA77: 0 | AB77: 0 | AC77: 0 | AD77: 0 | AE77: 0 | AF77: 0 | AG77: 0 | AH77: =Z77+AB77+AD77+AF77 -> 0 | AI77: =AA77+AC77+AE77+AG77 -> 0 | AJ77: 0 | AK77: 0 | AL77: =AJ77+AK77 -> 0 | AM77: 0 | AN77: 0 | AO77: 0 | AP77: 0 | AQ77: 30 | AR77: 1 | AS77: 0 | AT77: 0 | AU77: =AM77+AQ77 -> 30 | AV77: =AN77+AR77 -> 1 | AW77: =AO77+AS77 -> 0 | AX77: =AP77+AT77 -> 0 | AY77: =AU77+AW77 -> 30 | AZ77: =AV77+AX77 -> 1
B78: TOTAL | D78: =SUM(D6:D77) -> 36254 | E78: =SUM(E6:E77) -> 20177 | F78: =SUM(F6:F77) -> 0 | G78: =SUM(G6:G77) -> 15624 | H78: =SUM(H6:H77) -> 36254 | I78: =SUM(I6:I77) -> 35801 | J78: =SUM(J6:J77) -> 13148 | K78: =SUM(K6:K77) -> 5431 | ... AZ78: =SUM(AZ6:AZ77) -> 31145

Sheet 제품(TP)_제품수불부
M1: 열고 닫는 기능 추가 필요 (좌측으로) | R1: 열고 닫는 기능 추가 필요 (좌측으로) | U1: 열고 닫는 기능 추가 필요 (좌측으로) | Z1: 열고 닫는 기능 추가 필요 (좌측으로)
B2: 모델 Model | C2: 구분 Division | D2: BOH | E2: INPUT | N2: 기타입고 | S2: OUTPUT | V2: 기타출고 | AA2: LOSS | AB2: EOH WH0006
E3: 1 | F3: 2 | G3: 3 | H3: 4 | I3: 5 | J3: 6 | K3: 7 | L3: 8 | M3: 9=1+…+8 | N3: 1 | O3: 2 | P3: 3 | Q3: 4 | R3: 5=1+2+3+4 | S3: 1 | T3: 2 | U3: 3=1+2 | V3: 1 | W3: 2 | X3: 3 | Y3: 4 | Z3: 5=1+2+3+4
E4: NORMAL FG INPUT | G4: RW FROM LINE → FG-WAREHOUSE / REWORK 생산라인 → 완제품 창고 CELL 입고 | M4: T_INPUT | N4: RMA | O4: 반제품 (유상) | P4: 반제품 (무상) | Q4: 기타 | R4: 기타입고 | S4: SHIP (A 급) | T4: SHIP (B 급) | U4: T_OUTPUT | V4: Re-Sorting (재검사) | W4: Re-work (SI검사) | X4: 무상매출 | Y4: 기타 | Z4: 기타출고
E5: LAST-MONTH | F5: THIS-MONTH | G5: BACK-SHIP (SORTING) | H5: BACK-SHIP (PF-RW) | I5: BACK-SHIP (PL-RW) | J5: WH RETURN (SORTING) | K5: WH RETURN (PF-RW) | L5: WH RETURN (PL-RW) | S5: PAID | T5: PAID | AD5: 검증
B6: 7075P | C6: =VLOOKUP(B6,'재공품 (WIP)_생산실적'!$B$6:$C$88,2,FALSE) -> MP | D6: =IFERROR(VLOOKUP(B6,'(A) Inventory'!$A$7:$C$89,3,0),0) -> 10030 | E6: =IFERROR(VLOOKUP(B6,'(B) FGs'!$B$6:$D$55,3,0),0) -> 0 | F6: =IFERROR(VLOOKUP(B6,'(B) FGs'!$B$6:$E$55,4,0),0) -> 0 | G6: =IFERROR(VLOOKUP(B6,'(B) FGs'!$B$6:$G$55,6,0),0) -> 0 | H6: =IFERROR(VLOOKUP(B6,'(B) FGs'!$B$6:$H$55,7,0),0) -> 0 | I6: =IFERROR(VLOOKUP(B6,'(B) FGs'!$B$6:$I$55,8,0),0) -> 0 | J6: =IFERROR(VLOOKUP(B6,'(B) FGs'!$B$6:$J$55,9,0),0) -> 0 | K6: =IFERROR(VLOOKUP(B6,'(B) FGs'!$B$6:$K$55,10,0),0) -> 0 | L6: =IFERROR(VLOOKUP(B6,'(B) FGs'!$B$6:$L$55,11,0),0) -> 0 | M6: =SUM(E6:L6) -> 0 | N6: =IFERROR(VLOOKUP(B6,'(B) FGs'!$B$6:$R$55,13,0),0) -> 0 | O6: =IFERROR(VLOOKUP(B6,'(A) Inventory'!$A$7:$R$89,18,0),0) -> 0 | P6: =IFERROR(VLOOKUP(B6,'(A) Inventory'!$A$7:$S$89,19,0),0) -> 0 | Q6: 0 | R6: =SUM(N6:Q6) -> 0 | S6: =IFERROR(VLOOKUP(B6,'(A) Inventory'!$A$7:$P$89,16,0),0) -> 0 | T6: =IFERROR(VLOOKUP(B6,'(A) Inventory'!$A$7:$R$89,18,0),0) -> 0 | U6: =SUM(S6:T6) -> 0 | V6: =IFERROR(VLOOKUP(B6,'(B) FGs'!$B$6:$S$55,18,0),0)-IFERROR(VLOOKUP(B6,'(B) FGs'!$B$6:$M$55,12,0),0) -> 0 | W6: =IFERROR(VLOOKUP(B6,'(B) FGs'!$B$6:$M$55,12,0),0) -> 0 | X6: =IFERROR(VLOOKUP(B6,'(A) Inventory'!$A$7:$S$89,19,0),0) -> 0 | Y6: 0 | Z6: =SUM(V6:Y6) -> 0 | AA6: 0 | AB6: 10030 | AD6: =D6+M6+R6-U6-Z6-AA6=AB6 -> TRUE | AE6: =D6+M6+R6-U6-Z6-AA6-AB6 -> 0
B7: 712TP | C7: =VLOOKUP(B7,'재공품 (WIP)_생산실적'!$B$6:$C$88,2,FALSE) -> MP | D7: =IFERROR(VLOOKUP(B7,'(A) Inventory'!$A$7:$C$89,3,0),0) -> 0 | E7: =IFERROR(VLOOKUP(B7,'(B) FGs'!$B$6:$D$55,3,0),0) -> 0 | F7: =IFERROR(VLOOKUP(B7,'(B) FGs'!$B$6:$E$55,4,0),0) -> 0 | G7: =IFERROR(VLOOKUP(B7,'(B) FGs'!$B$6:$G$55,6,0),0) -> 0 | H7: =IFERROR(VLOOKUP(B7,'(B) FGs'!$B$6:$H$55,7,0),0) -> 0 | I7: =IFERROR(VLOOKUP(B7,'(B) FGs'!$B$6:$I$55,8,0),0) -> 0 | J7: =IFERROR(VLOOKUP(B7,'(B) FGs'!$B$6:$J$55,9,0),0) -> 0 | K7: 0 | L7: =IFERROR(VLOOKUP(B7,'(B) FGs'!$B$6:$L$55,11,0),0) -> 0 | M7: =SUM(E7:L7) -> 0 | N7: =IFERROR(VLOOKUP(B7,'(B) FGs'!$B$6:$R$55,13,0),0) -> 0 | O7: =IFERROR(VLOOKUP(B7,'(A) Inventory'!$A$7:$R$89,18,0),0) -> 0 | P7: =IFERROR(VLOOKUP(B7,'(A) Inventory'!$A$7:$S$89,19,0),0) -> 0 | Q7: 0 | R7: =SUM(N7:Q7) -> 0 | S7: =IFERROR(VLOOKUP(B7,'(A) Inventory'!$A$7:$P$89,16,0),0) -> 0 | T7: =IFERROR(VLOOKUP(B7,'(A) Inventory'!$A$7:$R$89,18,0),0) -> 0 | U7: =SUM(S7:T7) -> 0 | V7: =IFERROR(VLOOKUP(B7,'(B) FGs'!$B$6:$S$55,18,0),0)-IFERROR(VLOOKUP(B7,'(B) FGs'!$B$6:$M$55,12,0),0) -> 0 | W7: =IFERROR(VLOOKUP(B7,'(B) FGs'!$B$6:$M$55,12,0),0) -> 0 | X7: =IFERROR(VLOOKUP(B7,'(A) Inventory'!$A$7:$S$89,19,0),0) -> 0 | Y7: 0 | Z7: =SUM(V7:Y7) -> 0 | AA7: 0 | AB7: 0 | AD7: =D7+M7+R7-U7-Z7-AA7=AB7 -> TRUE | AE7: =D7+M7+R7-U7-Z7-AA7-AB7 -> 0
B8: 716AP | C8: =VLOOKUP(B8,'재공품 (WIP)_생산실적'!$B$6:$C$88,2,FALSE) -> MP | D8: =IFERROR(VLOOKUP(B8,'(A) Inventory'!$A$7:$C$89,3,0),0) -> 387259 | E8: =IFERROR(VLOOKUP(B8,'(B) FGs'!$B$6:$D$55,3,0),0) -> 39672 | F8: =IFERROR(VLOOKUP(B8,'(B) FGs'!$B$6:$E$55,4,0),0) -> 441648 | G8: =IFERROR(VLOOKUP(B8,'(B) FGs'!$B$6:$G$55,6,0),0) -> 23934 | H8: =IFERROR(VLOOKUP(B8,'(B) FGs'!$B$6:$H$55,7,0),0) -> 0 | I8: =IFERROR(VLOOKUP(B8,'(B) FGs'!$B$6:$I$55,8,0),0) -> 0 | J8: =IFERROR(VLOOKUP(B8,'(B) FGs'!$B$6:$J$55,9,0),0) -> 242656 | K8: 9765 | L8: =IFERROR(VLOOKUP(B8,'(B) FGs'!$B$6:$L$55,11,0),0) -> 0 | M8: =SUM(E8:L8) -> 757675 | N8: =IFERROR(VLOOKUP(B8,'(B) FGs'!$B$6:$R$55,13,0),0) -> 0 | O8: =IFERROR(VLOOKUP(B8,'(A) Inventory'!$A$7:$R$89,18,0),0) -> 10 | P8: =IFERROR(VLOOKUP(B8,'(A) Inventory'!$A$7:$S$89,19,0),0) -> 5 | Q8: 0 | R8: =SUM(N8:Q8) -> 15 | S8: =IFERROR(VLOOKUP(B8,'(A) Inventory'!$A$7:$P$89,16,0),0) -> 594080 | T8: =IFERROR(VLOOKUP(B8,'(A) Inventory'!$A$7:$R$89,18,0),0) -> 10 | U8: =SUM(S8:T8) -> 594090 | V8: =IFERROR(VLOOKUP(B8,'(B) FGs'!$B$6:$S$55,18,0),0)-IFERROR(VLOOKUP(B8,'(B) FGs'!$B$6:$M$55,12,0),0) -> 260558 | W8: =IFERROR(VLOOKUP(B8,'(B) FGs'!$B$6:$M$55,12,0),0) -> 9765 | X8: =IFERROR(VLOOKUP(B8,'(A) Inventory'!$A$7:$S$89,19,0),0) -> 5 | Y8: 0 | Z8: =SUM(V8:Y8) -> 270328 | AA8: 0 | AB8: 280531 | AD8: =D8+M8+R8-U8-Z8-AA8=AB8 -> TRUE | AE8: =D8+M8+R8-U8-Z8-AA8-AB8 -> 0
B9: 716BD | C9: =VLOOKUP(B9,'재공품 (WIP)_생산실적'!$B$6:$C$88,2,FALSE) -> R&D | D9: =IFERROR(VLOOKUP(B9,'(A) Inventory'!$A$7:$C$89,3,0),0) -> 987 | E9: =IFERROR(VLOOKUP(B9,'(B) FGs'!$B$6:$D$55,3,0),0) -> 0 | F9: =IFERROR(VLOOKUP(B9,'(B) FGs'!$B$6:$E$55,4,0),0) -> 0 | G9: =IFERROR(VLOOKUP(B9,'(B) FGs'!$B$6:$G$55,6,0),0) -> 0 | H9: =IFERROR(VLOOKUP(B9,'(B) FGs'!$B$6:$H$55,7,0),0) -> 0 | I9: =IFERROR(VLOOKUP(B9,'(B) FGs'!$B$6:$I$55,8,0),0) -> 0 | J9: =IFERROR(VLOOKUP(B9,'(B) FGs'!$B$6:$J$55,9,0),0) -> 0 | K9: 0 | L9: =IFERROR(VLOOKUP(B9,'(B) FGs'!$B$6:$L$55,11,0),0) -> 0 | M9: =SUM(E9:L9) -> 0 | N9: =IFERROR(VLOOKUP(B9,'(B) FGs'!$B$6:$R$55,13,0),0) -> 0 | O9: =IFERROR(VLOOKUP(B9,'(A) Inventory'!$A$7:$R$89,18,0),0) -> 0 | P9: =IFERROR(VLOOKUP(B9,'(A) Inventory'!$A$7:$S$89,19,0),0) -> 0 | Q9: 0 | R9: =SUM(N9:Q9) -> 0 | S9: =IFERROR(VLOOKUP(B9,'(A) Inventory'!$A$7:$P$89,16,0),0) -> 0 | T9: =IFERROR(VLOOKUP(B9,'(A) Inventory'!$A$7:$R$89,18,0),0) -> 0 | U9: =SUM(S9:T9) -> 0 | V9: =IFERROR(VLOOKUP(B9,'(B) FGs'!$B$6:$S$55,18,0),0)-IFERROR(VLOOKUP(B9,'(B) FGs'!$B$6:$M$55,12,0),0) -> 0 | W9: =IFERROR(VLOOKUP(B9,'(B) FGs'!$B$6:$M$55,12,0),0) -> 0 | X9: =IFERROR(VLOOKUP(B9,'(A) Inventory'!$A$7:$S$89,19,0),0) -> 0 | Y9: 0 | Z9: =SUM(V9:Y9) -> 0 | AA9: 0 | AB9: 987 | AD9: =D9+M9+R9-U9-Z9-AA9=AB9 -> TRUE | AE9: =D9+M9+R9-U9-Z9-AA9-AB9 -> 0
B10: 716CD | C10: =VLOOKUP(B10,'재공품 (WIP)_생산실적'!$B$6:$C$88,2,FALSE) -> R&D | D10: =IFERROR(VLOOKUP(B10,'(A) Inventory'!$A$7:$C$89,3,0),0) -> 38 | E10: =IFERROR(VLOOKUP(B10,'(B) FGs'!$B$6:$D$55,3,0),0) -> 0 | F10: =IFERROR(VLOOKUP(B10,'(B) FGs'!$B$6:$E$55,4,0),0) -> 0 | G10: =IFERROR(VLOOKUP(B10,'(B) FGs'!$B$6:$G$55,6,0),0) -> 0 | H10: =IFERROR(VLOOKUP(B10,'(B) FGs'!$B$6:$H$55,7,0),0) -> 0 | I10: =IFERROR(VLOOKUP(B10,'(B) FGs'!$B$6:$I$55,8,0),0) -> 0 | J10: =IFERROR(VLOOKUP(B10,'(B) FGs'!$B$6:$J$55,9,0),0) -> 0 | K10: 0 | L10: =IFERROR(VLOOKUP(B10,'(B) FGs'!$B$6:$L$55,11,0),0) -> 0 | M10: =SUM(E10:L10) -> 0 | N10: =IFERROR(VLOOKUP(B10,'(B) FGs'!$B$6:$R$55,13,0),0) -> 0 | O10: =IFERROR(VLOOKUP(B10,'(A) Inventory'!$A$7:$R$89,18,0),0) -> 0 | P10: =IFERROR(VLOOKUP(B10,'(A) Inventory'!$A$7:$S$89,19,0),0) -> 0 | Q10: 0 | R10: =SUM(N10:Q10) -> 0 | S10: =IFERROR(VLOOKUP(B10,'(A) Inventory'!$A$7:$P$89,16,0),0) -> 0 | T10: =IFERROR(VLOOKUP(B10,'(A) Inventory'!$A$7:$R$89,18,0),0) -> 0 | U10: =SUM(S10:T10) -> 0 | V10: =IFERROR(VLOOKUP(B10,'(B) FGs'!$B$6:$S$55,18,0),0)-IFERROR(VLOOKUP(B10,'(B) FGs'!$B$6:$M$55,12,0),0) -> 0 | W10: =IFERROR(VLOOKUP(B10,'(B) FGs'!$B$6:$M$55,12,0),0) -> 0 | X10: =IFERROR(VLOOKUP(B10,'(A) Inventory'!$A$7:$S$89,19,0),0) -> 0 | Y10: 0 | Z10: =SUM(V10:Y10) -> 0 | AA10: 0 | AB10: 38 | AD10: =D10+M10+R10-U10-Z10-AA10=AB10 -> TRUE | AE10: =D10+M10+R10-U10-Z10-AA10-AB10 -> 0
B11: 716DD | C11: =VLOOKUP(B11,'재공품 (WIP)_생산실적'!$B$6:$C$88,2,FALSE) -> R&D | D11: =IFERROR(VLOOKUP(B11,'(A) Inventory'!$A$7:$C$89,3,0),0) -> 14976 | E11: =IFERROR(VLOOKUP(B11,'(B) FGs'!$B$6:$D$55,3,0),0) -> 0 | F11: =IFERROR(VLOOKUP(B11,'(B) FGs'!$B$6:$E$55,4,0),0) -> 0 | G11: =IFERROR(VLOOKUP(B11,'(B) FGs'!$B$6:$G$55,6,0),0) -> 0 | H11: =IFERROR(VLOOKUP(B11,'(B) FGs'!$B$6:$H$55,7,0),0) -> 0 | I11: =IFERROR(VLOOKUP(B11,'(B) FGs'!$B$6:$I$55,8,0),0) -> 0 | J11: =IFERROR(VLOOKUP(B11,'(B) FGs'!$B$6:$J$55,9,0),0) -> 0 | K11: 0 | L11: =IFERROR(VLOOKUP(B11,'(B) FGs'!$B$6:$L$55,11,0),0) -> 0 | M11: =SUM(E11:L11) -> 0 | N11: =IFERROR(VLOOKUP(B11,'(B) FGs'!$B$6:$R$55,13,0),0) -> 0 | O11: =IFERROR(VLOOKUP(B11,'(A) Inventory'!$A$7:$R$89,18,0),0) -> 0 | P11: =IFERROR(VLOOKUP(B11,'(A) Inventory'!$A$7:$S$89,19,0),0) -> 0 | Q11: 0 | R11: =SUM(N11:Q11) -> 0 | S11: =IFERROR(VLOOKUP(B11,'(A) Inventory'!$A$7:$P$89,16,0),0) -> 0 | T11: =IFERROR(VLOOKUP(B11,'(A) Inventory'!$A$7:$R$89,18,0),0) -> 0 | U11: =SUM(S11:T11) -> 0 | V11: =IFERROR(VLOOKUP(B11,'(B) FGs'!$B$6:$S$55,18,0),0)-IFERROR(VLOOKUP(B11,'(B) FGs'!$B$6:$M$55,12,0),0) -> 0 | W11: =IFERROR(VLOOKUP(B11,'(B) FGs'!$B$6:$M$55,12,0),0) -> 0 | X11: =IFERROR(VLOOKUP(B11,'(A) Inventory'!$A$7:$S$89,19,0),0) -> 0 | Y11: 0 | Z11: =SUM(V11:Y11) -> 0 | AA11: 0 | AB11: 14976 | AD11: =D11+M11+R11-U11-Z11-AA11=AB11 -> TRUE | AE11: =D11+M11+R11-U11-Z11-AA11-AB11 -> 0
B12: 716DTT | C12: =VLOOKUP(B12,'재공품 (WIP)_생산실적'!$B$6:$C$88,2,FALSE) -> R&D | D12: =IFERROR(VLOOKUP(B12,'(A) Inventory'!$A$7:$C$89,3,0),0) -> 0 | E12: =IFERROR(VLOOKUP(B12,'(B) FGs'!$B$6:$D$55,3,0),0) -> 0 | F12: =IFERROR(VLOOKUP(B12,'(B) FGs'!$B$6:$E$55,4,0),0) -> 0 | G12: =IFERROR(VLOOKUP(B12,'(B) FGs'!$B$6:$G$55,6,0),0) -> 0 | H12: =IFERROR(VLOOKUP(B12,'(B) FGs'!$B$6:$H$55,7,0),0) -> 0 | I12: =IFERROR(VLOOKUP(B12,'(B) FGs'!$B$6:$I$55,8,0),0) -> 0 | J12: =IFERROR(VLOOKUP(B12,'(B) FGs'!$B$6:$J$55,9,0),0) -> 0 | K12: 0 | L12: =IFERROR(VLOOKUP(B12,'(B) FGs'!$B$6:$L$55,11,0),0) -> 0 | M12: =SUM(E12:L12) -> 0 | N12: =IFERROR(VLOOKUP(B12,'(B) FGs'!$B$6:$R$55,13,0),0) -> 0 | O12: =IFERROR(VLOOKUP(B12,'(A) Inventory'!$A$7:$R$89,18,0),0) -> 0 | P12: =IFERROR(VLOOKUP(B12,'(A) Inventory'!$A$7:$S$89,19,0),0) -> 300 | Q12: 0 | R12: =SUM(N12:Q12) -> 300 | S12: =IFERROR(VLOOKUP(B12,'(A) Inventory'!$A$7:$P$89,16,0),0) -> 0 | T12: =IFERROR(VLOOKUP(B12,'(A) Inventory'!$A$7:$R$89,18,0),0) -> 0 | U12: =SUM(S12:T12) -> 0 | V12: =IFERROR(VLOOKUP(B12,'(B) FGs'!$B$6:$S$55,18,0),0)-IFERROR(VLOOKUP(B12,'(B) FGs'!$B$6:$M$55,12,0),0) -> 0 | W12: =IFERROR(VLOOKUP(B12,'(B) FGs'!$B$6:$M$55,12,0),0) -> 0 | X12: =IFERROR(VLOOKUP(B12,'(A) Inventory'!$A$7:$S$89,19,0),0) -> 300 | Y12: 0 | Z12: =SUM(V12:Y12) -> 300 | AA12: 0 | AB12: 0 | AD12: =D12+M12+R12-U12-Z12-AA12=AB12 -> TRUE | AE12: =D12+M12+R12-U12-Z12-AA12-AB12 -> 0
B13: 716ED | C13: =VLOOKUP(B13,'재공품 (WIP)_생산실적'!$B$6:$C$88,2,FALSE) -> R&D | D13: =IFERROR(VLOOKUP(B13,'(A) Inventory'!$A$7:$C$89,3,0),0) -> 0 | E13: =IFERROR(VLOOKUP(B13,'(B) FGs'!$B$6:$D$55,3,0),0) -> 0 | F13: =IFERROR(VLOOKUP(B13,'(B) FGs'!$B$6:$E$55,4,0),0) -> 0 | G13: =IFERROR(VLOOKUP(B13,'(B) FGs'!$B$6:$G$55,6,0),0) -> 0 | H13: =IFERROR(VLOOKUP(B13,'(B) FGs'!$B$6:$H$55,7,0),0) -> 0 | I13: =IFERROR(VLOOKUP(B13,'(B) FGs'!$B$6:$I$55,8,0),0) -> 0 | J13: =IFERROR(VLOOKUP(B13,'(B) FGs'!$B$6:$J$55,9,0),0) -> 0 | K13: 0 | L13: =IFERROR(VLOOKUP(B13,'(B) FGs'!$B$6:$L$55,11,0),0) -> 0 | M13: =SUM(E13:L13) -> 0 | N13: =IFERROR(VLOOKUP(B13,'(B) FGs'!$B$6:$R$55,13,0),0) -> 0 | O13: =IFERROR(VLOOKUP(B13,'(A) Inventory'!$A$7:$R$89,18,0),0) -> 0 | P13: =IFERROR(VLOOKUP(B13,'(A) Inventory'!$A$7:$S$89,19,0),0) -> 0 | Q13: 0 | R13: =SUM(N13:Q13) -> 0 | S13: =IFERROR(VLOOKUP(B13,'(A) Inventory'!$A$7:$P$89,16,0),0) -> 0 | T13: =IFERROR(VLOOKUP(B13,'(A) Inventory'!$A$7:$R$89,18,0),0) -> 0 | U13: =SUM(S13:T13) -> 0 | V13: =IFERROR(VLOOKUP(B13,'(B) FGs'!$B$6:$S$55,18,0),0)-IFERROR(VLOOKUP(B13,'(B) FGs'!$B$6:$M$55,12,0),0) -> 0 | W13: =IFERROR(VLOOKUP(B13,'(B) FGs'!$B$6:$M$55,12,0),0) -> 0 | X13: =IFERROR(VLOOKUP(B13,'(A) Inventory'!$A$7:$S$89,19,0),0) -> 0 | Y13: 0 | Z13: =SUM(V13:Y13) -> 0 | AA13: 0 | AB13: 0 | AD13: =D13+M13+R13-U13-Z13-AA13=AB13 -> TRUE | AE13: =D13+M13+R13-U13-Z13-AA13-AB13 -> 0
B14: 716ETT | C14: =VLOOKUP(B14,'재공품 (WIP)_생산실적'!$B$6:$C$88,2,FALSE) -> R&D | D14: =IFERROR(VLOOKUP(B14,'(A) Inventory'!$A$7:$C$89,3,0),0) -> 0 | E14: =IFERROR(VLOOKUP(B14,'(B) FGs'!$B$6:$D$55,3,0),0) -> 0 | F14: =IFERROR(VLOOKUP(B14,'(B) FGs'!$B$6:$E$55,4,0),0) -> 0 | G14: =IFERROR(VLOOKUP(B14,'(B) FGs'!$B$6:$G$55,6,0),0) -> 0 | H14: =IFERROR(VLOOKUP(B14,'(B) FGs'!$B$6:$H$55,7,0),0) -> 0 | I14: =IFERROR(VLOOKUP(B14,'(B) FGs'!$B$6:$I$55,8,0),0) -> 0 | J14: =IFERROR(VLOOKUP(B14,'(B) FGs'!$B$6:$J$55,9,0),0) -> 0 | K14: 0 | L14: =IFERROR(VLOOKUP(B14,'(B) FGs'!$B$6:$L$55,11,0),0) -> 0 | M14: =SUM(E14:L14) -> 0 | N14: =IFERROR(VLOOKUP(B14,'(B) FGs'!$B$6:$R$55,13,0),0) -> 0 | O14: =IFERROR(VLOOKUP(B14,'(A) Inventory'!$A$7:$R$89,18,0),0) -> 350 | P14: =IFERROR(VLOOKUP(B14,'(A) Inventory'!$A$7:$S$89,19,0),0) -> 0 | Q14: 0 | R14: =SUM(N14:Q14) -> 350 | S14: =IFERROR(VLOOKUP(B14,'(A) Inventory'!$A$7:$P$89,16,0),0) -> 0 | T14: =IFERROR(VLOOKUP(B14,'(A) Inventory'!$A$7:$R$89,18,0),0) -> 350 | U14: =SUM(S14:T14) -> 350 | V14: =IFERROR(VLOOKUP(B14,'(B) FGs'!$B$6:$S$55,18,0),0)-IFERROR(VLOOKUP(B14,'(B) FGs'!$B$6:$M$55,12,0),0) -> 0 | W14: =IFERROR(VLOOKUP(B14,'(B) FGs'!$B$6:$M$55,12,0),0) -> 0 | X14: =IFERROR(VLOOKUP(B14,'(A) Inventory'!$A$7:$S$89,19,0),0) -> 0 | Y14: 0 | Z14: =SUM(V14:Y14) -> 0 | AA14: 0 | AB14: 0 | AD14: =D14+M14+R14-U14-Z14-AA14=AB14 -> TRUE | AE14: =D14+M14+R14-U14-Z14-AA14-AB14 -> 0
B15: 716FD | C15: =VLOOKUP(B15,'재공품 (WIP)_생산실적'!$B$6:$C$88,2,FALSE) -> R&D | D15: =IFERROR(VLOOKUP(B15,'(A) Inventory'!$A$7:$C$89,3,0),0) -> 0 | E15: =IFERROR(VLOOKUP(B15,'(B) FGs'!$B$6:$D$55,3,0),0) -> 0 | F15: =IFERROR(VLOOKUP(B15,'(B) FGs'!$B$6:$E$55,4,0),0) -> 0 | G15: =IFERROR(VLOOKUP(B15,'(B) FGs'!$B$6:$G$55,6,0),0) -> 0 | H15: =IFERROR(VLOOKUP(B15,'(B) FGs'!$B$6:$H$55,7,0),0) -> 0 | I15: =IFERROR(VLOOKUP(B15,'(B) FGs'!$B$6:$I$55,8,0),0) -> 0 | J15: =IFERROR(VLOOKUP(B15,'(B) FGs'!$B$6:$J$55,9,0),0) -> 0 | K15: 0 | L15: =IFERROR(VLOOKUP(B15,'(B) FGs'!$B$6:$L$55,11,0),0) -> 0 | M15: =SUM(E15:L15) -> 0 | N15: =IFERROR(VLOOKUP(B15,'(B) FGs'!$B$6:$R$55,13,0),0) -> 0 | O15: =IFERROR(VLOOKUP(B15,'(A) Inventory'!$A$7:$R$89,18,0),0) -> 0 | P15: =IFERROR(VLOOKUP(B15,'(A) Inventory'!$A$7:$S$89,19,0),0) -> 0 | Q15: 0 | R15: =SUM(N15:Q15) -> 0 | S15: =IFERROR(VLOOKUP(B15,'(A) Inventory'!$A$7:$P$89,16,0),0) -> 0 | T15: =IFERROR(VLOOKUP(B15,'(A) Inventory'!$A$7:$R$89,18,0),0) -> 0 | U15: =SUM(S15:T15) -> 0 | V15: =IFERROR(VLOOKUP(B15,'(B) FGs'!$B$6:$S$55,18,0),0)-IFERROR(VLOOKUP(B15,'(B) FGs'!$B$6:$M$55,12,0),0) -> 0 | W15: =IFERROR(VLOOKUP(B15,'(B) FGs'!$B$6:$M$55,12,0),0) -> 0 | X15: =IFERROR(VLOOKUP(B15,'(A) Inventory'!$A$7:$S$89,19,0),0) -> 0 | Y15: 0 | Z15: =SUM(V15:Y15) -> 0 | AA15: 0 | AB15: 0 | AD15: =D15+M15+R15-U15-Z15-AA15=AB15 -> TRUE | AE15: =D15+M15+R15-U15-Z15-AA15-AB15 -> 0
B16: 716GD | C16: =VLOOKUP(B16,'재공품 (WIP)_생산실적'!$B$6:$C$88,2,FALSE) -> R&D | D16: =IFERROR(VLOOKUP(B16,'(A) Inventory'!$A$7:$C$89,3,0),0) -> 0 | E16: =IFERROR(VLOOKUP(B16,'(B) FGs'!$B$6:$D$55,3,0),0) -> 0 | F16: =IFERROR(VLOOKUP(B16,'(B) FGs'!$B$6:$E$55,4,0),0) -> 0 | G16: =IFERROR(VLOOKUP(B16,'(B) FGs'!$B$6:$G$55,6,0),0) -> 0 | H16: =IFERROR(VLOOKUP(B16,'(B) FGs'!$B$6:$H$55,7,0),0) -> 0 | I16: =IFERROR(VLOOKUP(B16,'(B) FGs'!$B$6:$I$55,8,0),0) -> 0 | J16: =IFERROR(VLOOKUP(B16,'(B) FGs'!$B$6:$J$55,9,0),0) -> 0 | K16: 0 | L16: =IFERROR(VLOOKUP(B16,'(B) FGs'!$B$6:$L$55,11,0),0) -> 0 | M16: =SUM(E16:L16) -> 0 | N16: =IFERROR(VLOOKUP(B16,'(B) FGs'!$B$6:$R$55,13,0),0) -> 0 | O16: =IFERROR(VLOOKUP(B16,'(A) Inventory'!$A$7:$R$89,18,0),0) -> 0 | P16: =IFERROR(VLOOKUP(B16,'(A) Inventory'!$A$7:$S$89,19,0),0) -> 0 | Q16: 0 | R16: =SUM(N16:Q16) -> 0 | S16: =IFERROR(VLOOKUP(B16,'(A) Inventory'!$A$7:$P$89,16,0),0) -> 0 | T16: =IFERROR(VLOOKUP(B16,'(A) Inventory'!$A$7:$R$89,18,0),0) -> 0 | U16: =SUM(S16:T16) -> 0 | V16: =IFERROR(VLOOKUP(B16,'(B) FGs'!$B$6:$S$55,18,0),0)-IFERROR(VLOOKUP(B16,'(B) FGs'!$B$6:$M$55,12,0),0) -> 0 | W16: =IFERROR(VLOOKUP(B16,'(B) FGs'!$B$6:$M$55,12,0),0) -> 0 | X16: =IFERROR(VLOOKUP(B16,'(A) Inventory'!$A$7:$S$89,19,0),0) -> 0 | Y16: 0 | Z16: =SUM(V16:Y16) -> 0 | AA16: 0 | AB16: 0 | AD16: =D16+M16+R16-U16-Z16-AA16=AB16 -> TRUE | AE16: =D16+M16+R16-U16-Z16-AA16-AB16 -> 0
B17: 716JD | C17: =VLOOKUP(B17,'재공품 (WIP)_생산실적'!$B$6:$C$88,2,FALSE) -> R&D | D17: =IFERROR(VLOOKUP(B17,'(A) Inventory'!$A$7:$C$89,3,0),0) -> 3773 | E17: =IFERROR(VLOOKUP(B17,'(B) FGs'!$B$6:$D$55,3,0),0) -> 0 | F17: =IFERROR(VLOOKUP(B17,'(B) FGs'!$B$6:$E$55,4,0),0) -> 0 | G17: =IFERROR(VLOOKUP(B17,'(B) FGs'!$B$6:$G$55,6,0),0) -> 0 | H17: =IFERROR(VLOOKUP(B17,'(B) FGs'!$B$6:$H$55,7,0),0) -> 0 | I17: =IFERROR(VLOOKUP(B17,'(B) FGs'!$B$6:$I$55,8,0),0) -> 0 | J17: =IFERROR(VLOOKUP(B17,'(B) FGs'!$B$6:$J$55,9,0),0) -> 0 | K17: 0 | L17: =IFERROR(VLOOKUP(B17,'(B) FGs'!$B$6:$L$55,11,0),0) -> 0 | M17: =SUM(E17:L17) -> 0 | N17: =IFERROR(VLOOKUP(B17,'(B) FGs'!$B$6:$R$55,13,0),0) -> 0 | O17: =IFERROR(VLOOKUP(B17,'(A) Inventory'!$A$7:$R$89,18,0),0) -> 0 | P17: =IFERROR(VLOOKUP(B17,'(A) Inventory'!$A$7:$S$89,19,0),0) -> 0 | Q17: 0 | R17: =SUM(N17:Q17) -> 0 | S17: =IFERROR(VLOOKUP(B17,'(A) Inventory'!$A$7:$P$89,16,0),0) -> 0 | T17: =IFERROR(VLOOKUP(B17,'(A) Inventory'!$A$7:$R$89,18,0),0) -> 0 | U17: =SUM(S17:T17) -> 0 | V17: =IFERROR(VLOOKUP(B17,'(B) FGs'!$B$6:$S$55,18,0),0)-IFERROR(VLOOKUP(B17,'(B) FGs'!$B$6:$M$55,12,0),0) -> 0 | W17: =IFERROR(VLOOKUP(B17,'(B) FGs'!$B$6:$M$55,12,0),0) -> 0 | X17: =IFERROR(VLOOKUP(B17,'(A) Inventory'!$A$7:$S$89,19,0),0) -> 0 | Y17: 0 | Z17: =SUM(V17:Y17) -> 0 | AA17: 0 | AB17: 3773 | AD17: =D17+M17+R17-U17-Z17-AA17=AB17 -> TRUE | AE17: =D17+M17+R17-U17-Z17-AA17-AB17 -> 0
B18: 716KD | C18: =VLOOKUP(B18,'재공품 (WIP)_생산실적'!$B$6:$C$88,2,FALSE) -> R&D | D18: =IFERROR(VLOOKUP(B18,'(A) Inventory'!$A$7:$C$89,3,0),0) -> 1943 | E18: =IFERROR(VLOOKUP(B18,'(B) FGs'!$B$6:$D$55,3,0),0) -> 393 | F18: =IFERROR(VLOOKUP(B18,'(B) FGs'!$B$6:$E$55,4,0),0) -> 0 | G18: =IFERROR(VLOOKUP(B18,'(B) FGs'!$B$6:$G$55,6,0),0) -> 0 | H18: =IFERROR(VLOOKUP(B18,'(B) FGs'!$B$6:$H$55,7,0),0) -> 0 | I18: =IFERROR(VLOOKUP(B18,'(B) FGs'!$B$6:$I$55,8,0),0) -> 0 | J18: =IFERROR(VLOOKUP(B18,'(B) FGs'!$B$6:$J$55,9,0),0) -> 0 | K18: 0 | L18: =IFERROR(VLOOKUP(B18,'(B) FGs'!$B$6:$L$55,11,0),0) -> 0 | M18: =SUM(E18:L18) -> 393 | N18: =IFERROR(VLOOKUP(B18,'(B) FGs'!$B$6:$R$55,13,0),0) -> 0 | O18: =IFERROR(VLOOKUP(B18,'(A) Inventory'!$A$7:$R$89,18,0),0) -> 0 | P18: =IFERROR(VLOOKUP(B18,'(A) Inventory'!$A$7:$S$89,19,0),0) -> 0 | Q18: 0 | R18: =SUM(N18:Q18) -> 0 | S18: =IFERROR(VLOOKUP(B18,'(A) Inventory'!$A$7:$P$89,16,0),0) -> 0 | T18: =IFERROR(VLOOKUP(B18,'(A) Inventory'!$A$7:$R$89,18,0),0) -> 0 | U18: =SUM(S18:T18) -> 0 | V18: =IFERROR(VLOOKUP(B18,'(B) FGs'!$B$6:$S$55,18,0),0)-IFERROR(VLOOKUP(B18,'(B) FGs'!$B$6:$M$55,12,0),0) -> 0 | W18: =IFERROR(VLOOKUP(B18,'(B) FGs'!$B$6:$M$55,12,0),0) -> 0 | X18: =IFERROR(VLOOKUP(B18,'(A) Inventory'!$A$7:$S$89,19,0),0) -> 0 | Y18: 0 | Z18: =SUM(V18:Y18) -> 0 | AA18: 0 | AB18: 2336 | AD18: =D18+M18+R18-U18-Z18-AA18=AB18 -> TRUE | AE18: =D18+M18+R18-U18-Z18-AA18-AB18 -> 0
... B88: 8191D | C88: =VLOOKUP(B88,'재공품 (WIP)_생산실적'!$B$6:$C$88,2,FALSE) -> R&D | D88: =IFERROR(VLOOKUP(B88,'(A) Inventory'!$A$7:$C$89,3,0),0) -> 120 | E88: =IFERROR(VLOOKUP(B88,'(B) FGs'!$B$6:$D$55,3,0),0) -> 0 | F88: =IFERROR(VLOOKUP(B88,'(B) FGs'!$B$6:$E$55,4,0),0) -> 0 | G88: =IFERROR(VLOOKUP(B88,'(B) FGs'!$B$6:$G$55,6,0),0) -> 0 | H88: =IFERROR(VLOOKUP(B88,'(B) FGs'!$B$6:$H$55,7,0),0) -> 0 | I88: =IFERROR(VLOOKUP(B88,'(B) FGs'!$B$6:$I$55,8,0),0) -> 0 | J88: =IFERROR(VLOOKUP(B88,'(B) FGs'!$B$6:$J$55,9,0),0) -> 0 | K88: 0 | L88: =IFERROR(VLOOKUP(B88,'(B) FGs'!$B$6:$L$55,11,0),0) -> 0 | M88: =SUM(E88:L88) -> 0 | N88: =IFERROR(VLOOKUP(B88,'(B) FGs'!$B$6:$R$55,13,0),0) -> 0 | O88: =IFERROR(VLOOKUP(B88,'(A) Inventory'!$A$7:$R$89,18,0),0) -> 0 | P88: =IFERROR(VLOOKUP(B88,'(A) Inventory'!$A$7:$S$89,19,0),0) -> 0 | Q88: 0 | R88: =SUM(N88:Q88) -> 0 | S88: =IFERROR(VLOOKUP(B88,'(A) Inventory'!$A$7:$P$89,16,0),0) -> 0 | T88: =IFERROR(VLOOKUP(B88,'(A) Inventory'!$A$7:$R$89,18,0),0) -> 0 | U88: =SUM(S88:T88) -> 0 | V88: =IFERROR(VLOOKUP(B88,'(B) FGs'!$B$6:$S$55,18,0),0)-IFERROR(VLOOKUP(B88,'(B) FGs'!$B$6:$M$55,12,0),0) -> 0 | W88: =IFERROR(VLOOKUP(B88,'(B) FGs'!$B$6:$M$55,12,0),0) -> 0 | X88: =IFERROR(VLOOKUP(B88,'(A) Inventory'!$A$7:$S$89,19,0),0) -> 0 | Y88: 0 | Z88: =SUM(V88:Y88) -> 0 | AA88: 0 | AB88: 120 | AD88: =D88+M88+R88-U88-Z88-AA88=AB88 -> TRUE | AE88: =D88+M88+R88-U88-Z88-AA88-AB88 -> 0
B89: TOTAL | D89: =SUM(D6:D88) -> 679860 | E89: =SUM(E6:E88) -> 50800 | F89: =SUM(F6:F88) -> 646966 | G89: =SUM(G6:G88) -> 23934 | H89: =SUM(H6:H88) -> 0 | I89: =SUM(I6:I88) -> 0 | J89: =SUM(J6:J88) -> 257976 | K89: =SUM(K6:K88) -> 9997 | ... AB89: =SUM(AB6:AB88) -> 414135 | AD89: =D89+M89+R89-U89-Z89-AA89=AB89 -> TRUE | AE89: =D89+M89+R89-U89-Z89-AA89-AB89 -> 0

Sheet 재공품 (WIP) (제조원가_재공)
AB1: 열고 닫는 기능 추가 필요 (좌측으로) | AH1: 전월 재공평가 단가 사용 | AR1: 열고 닫는 기능 추가 필요 (좌측으로) | AV1: 전월 재공평가 단가 사용 | BL1: 열고 닫는 기능 추가 필요 (좌측으로) | CT1: 열고 닫는 기능 추가 필요 (좌측으로)
B2: 모델 Model | C2: 구분 Division | D2: 기초 / BOH | AF2: 입고 / INPUT | AH2: 기타입고 / Other Input (6=1+2+3+4+5) | AT2: 출고 / OUTPUT | AV2: 기타출고 / Other Output | BP2: LOSS (SCRAP) | BV2: 재고 / EOH
D3: 1 | H3: 2 | L3: 3=1+2 | P3: 4 | T3: 5 | X3: 6=4+5 | AB3: 7=3+6 | AF3: 1 | AH3: 1 | AJ3: 2 | AL3: 3 | AN3: 4 | AP3: 5 | AR3: 6 | AT3: 1 | AV3: 1 | AZ3: 2 | BD3: 3 | BH3: 4 | BL3: 5 | BV3: 1 | BZ3: 2 | CD3: 3 | CH3: 4 | CL3: 5 (1+3) | CP3: 6 (2+4) | CT3: TOTAL_EOH (MES) 7=5+6
D4: LINE_WIP | H4: LINE_FGS | L4: BOH A_LEVEL SUB TOTAL | P4: B_LEVEL_WIP | T4: B_LEVEL_FGS | X4: BOH B_LEVEL SUB TOTAL | AB4: T_BOH | AF4: USC_INPUT (C) | AH4: CODE 변경 | AJ4: Re-Sorting (재검사) | AL4: Re-work (SI검사) | AN4: 반제품 입고 | AP4: 기타 | AR4: 기타입고 | AT4: OUTPUT_A (C) | AV4: CODE 변경 | AZ4: 반제품 출고 (유상) | BD4: 반제품 출고 (무상) | BH4: 기타 | BL4: 기타출고 (5=1+2+3+4) | BV4: LINE_WIP (A) | BZ4: LINE_FGs (A) | CD4: B_LEVEL WIP (A) | CH4: B_LEVEL FGs | CL4: T_EOH WIP | CP4: T_EOH FGs
D5: PFL전 50% | F5: PFL후 90% | H5: PFL전 50% | J5: PFL후 90% | L5: PFL전 50% | N5: PFL후 90% | P5: PFL전 50% | R5: PFL후 90% | T5: PFL전 50% | V5: PFL후 90% | X5: PFL전 50% | Z5: PFL후 90% | AB5: PFL전 50% | AD5: PFL후 90% | AV5: PFL전 50% | AX5: PFL후 90% | AZ5: PFL전 50% | BB5: PFL후 90% | BD5: PFL전 50% | BF5: PFL후 90% | BH5: PFL전 50% | BJ5: PFL후 90% | BL5: PFL전 50% | BN5: PFL후 90% | BP5: PFL전 50% | BR5: PFL후 90% | BT5: 합계 | BV5: PFL전 50% | BX5: PFL후 90% | BZ5: PFL전 50% | CB5: PFL후 90% | CD5: PFL전 50% | CF5: PFL후 90% | CH5: PFL전 50% | CJ5: PFL후 90% | CL5: PFL전 50% | CN5: PFL후 90% | CP5: PFL전 50% | CR5: PFL후 90% | CT5: PFL전 50% | CV5: PFL후 90%
D6: 수량 | E6: 금액 | F6: 수량 | G6: 금액 | H6: 수량 | I6: 금액 | J6: 수량 | K6: 금액 | L6: 수량 | M6: 금액 | N6: 수량 | O6: 금액 | P6: 수량 | Q6: 금액 | R6: 수량 | S6: 금액 | T6: 수량 | U6: 금액 | V6: 수량 | W6: 금액 | X6: 수량 | Y6: 금액 | Z6: 수량 | AA6: 금액 | AB6: 수량 | AC6: 금액 | AD6: 수량 | AE6: 금액 | AF6: 수량 | AG6: 금액 | AH6: 수량 | AI6: 금액 | AJ6: 수량 | AK6: 금액 | AL6: 수량 | AM6: 금액 | AN6: 수량 | AO6: 금액 | AP6: 수량 | AQ6: 금액 | AR6: 수량 | AS6: 금액 | AT6: 수량 | AU6: 금액 | AV6: 수량 | AW6: 금액 | AX6: 수량 | AY6: 금액 | AZ6: 수량 | BA6: 금액 | BB6: 수량 | BC6: 금액 | BD6: 수량 | BE6: 금액 | BF6: 수량 | BG6: 금액 | BH6: 수량 | BI6: 금액 | BJ6: 수량 | BK6: 금액 | BL6: 수량 | BM6: 금액 | BN6: 수량 | BO6: 금액 | BP6: 수량 | BQ6: 금액 | BR6: 수량 | BS6: 금액 | BT6: 수량 | BU6: 금액 | BV6: 수량 | BW6: 금액 | BX6: 수량 | BY6: 금액 | BZ6: 수량 | CA6: 금액 | CB6: 수량 | CC6: 금액 | CD6: 수량 | CE6: 금액 | CF6: 수량 | CG6: 금액 | CH6: 수량 | CI6: 금액 | CJ6: 수량 | CK6: 금액 | CL6: 수량 | CM6: 금액 | CN6: 수량 | CO6: 금액 | CP6: 수량 | CQ6: 금액 | CR6: 수량 | CS6: 금액 | CT6: 수량 | CU6: 금액 | CV6: 수량 | CW6: 금액
B7: 7075P | C7: MP | D7: 0 | F7: 0 | H7: 0 | J7: 0 | L7: =D7+H7 -> 0 | M7: =E7+I7 -> 0 | N7: =F7+J7 -> 0 | O7: =G7+K7 -> 0 | P7: 6 | R7: 7 | T7: 0 | V7: 0 | X7: =P7+T7 -> 6 | Y7: =Q7+U7 -> 0 | Z7: =R7+V7 -> 7 | AA7: =S7+W7 -> 0 | AB7: =L7+X7 -> 6 | AC7: =M7+Y7 -> 0 | AD7: =N7+Z7 -> 7 | AE7: =O7+AA7 -> 0 | AF7: 0 | AH7: 0 | AJ7: 0 | AL7: 0 | AN7: 0 | AP7: 0 | AR7: =AH7+AJ7+AL7+AN7+AP7 -> 0 | AS7: =AI7+AK7+AM7+AO7+AQ7 -> 0 | AT7: 0 | AV7: 0 | AX7: 0 | AZ7: 0 | BB7: 0 | BD7: 0 | BF7: 0 | BH7: 0 | BJ7: 0 | BL7: =AV7+AX7+AZ7+BB7+BD7+BF7+BH7+BJ7 -> 0 | BM7: =AW7+AY7+BA7+BC7+BE7+BG7+BI7+BK7 -> 0 | BN7: =AX7+AZ7+BB7+BD7+BF7+BH7+BJ7+BL7 -> 0 | BO7: =AY7+BA7+BC7+BE7+BG7+BI7+BK7+BM7 -> 0 | BP7: 0 | BR7: 0 | BT7: =BP7+BR7 -> 0 | BU7: =BQ7+BS7 -> 0 | BV7: 0 | BX7: 0 | BZ7: 0 | CB7: 0 | CD7: 6 | CF7: 7 | CH7: 0 | CJ7: 0 | CL7: =BV7+CD7 -> 6 | CM7: =BW7+CE7 -> 0 | CN7: =BX7+CF7 -> 7 | CO7: =BY7+CG7 -> 0 | CP7: =BZ7+CH7 -> 0 | CQ7: =CA7+CI7 -> 0 | CR7: =CB7+CJ7 -> 0 | CS7: =CC7+CK7 -> 0 | CT7: =CL7+CP7 -> 6 | CU7: =CM7+CQ7 -> 0 | CV7: =CN7+CR7 -> 7 | CW7: =CO7+CS7 -> 0
B8: 712TP | C8: MP | D8: 0 | F8: 0 | H8: 0 | J8: 0 | L8: =D8+H8 -> 0 | M8: =E8+I8 -> 0 | N8: =F8+J8 -> 0 | O8: =G8+K8 -> 0 | P8: 173 | R8: 11 | T8: 0 | V8: 0 | X8: =P8+T8 -> 173 | Y8: =Q8+U8 -> 0 | Z8: =R8+V8 -> 11 | AA8: =S8+W8 -> 0 | AB8: =L8+X8 -> 173 | AC8: =M8+Y8 -> 0 | AD8: =N8+Z8 -> 11 | AE8: =O8+AA8 -> 0 | AF8: 0 | AH8: 0 | AJ8: 0 | AL8: 0 | AN8: 0 | AP8: 0 | AR8: =AH8+AJ8+AL8+AN8+AP8 -> 0 | AS8: =AI8+AK8+AM8+AO8+AQ8 -> 0 | AT8: 0 | AV8: 0 | AX8: 0 | AZ8: 0 | BB8: 0 | BD8: 0 | BF8: 0 | BH8: 0 | BJ8: 0 | BL8: =AV8+AX8+AZ8+BB8+BD8+BF8+BH8+BJ8 -> 0 | BM8: =AW8+AY8+BA8+BC8+BE8+BG8+BI8+BK8 -> 0 | BN8: =AX8+AZ8+BB8+BD8+BF8+BH8+BJ8+BL8 -> 0 | BO8: =AY8+BA8+BC8+BE8+BG8+BI8+BK8+BM8 -> 0 | BP8: 0 | BR8: 0 | BT8: =BP8+BR8 -> 0 | BU8: =BQ8+BS8 -> 0 | BV8: 0 | BX8: 0 | BZ8: 0 | CB8: 0 | CD8: 173 | CF8: 11 | CH8: 0 | CJ8: 0 | CL8: =BV8+CD8 -> 173 | CM8: =BW8+CE8 -> 0 | CN8: =BX8+CF8 -> 11 | CO8: =BY8+CG8 -> 0 | CP8: =BZ8+CH8 -> 0 | CQ8: =CA8+CI8 -> 0 | CR8: =CB8+CJ8 -> 0 | CS8: =CC8+CK8 -> 0 | CT8: =CL8+CP8 -> 173 | CU8: =CM8+CQ8 -> 0 | CV8: =CN8+CR8 -> 11 | CW8: =CO8+CS8 -> 0
B9: 716AP | C9: MP | D9: 30912 | F9: 17821 | H9: 0 | J9: 15621 | L9: =D9+H9 -> 30912 | M9: =E9+I9 -> 0 | N9: =F9+J9 -> 33442 | O9: =G9+K9 -> 0 | P9: 2246 | R9: 292 | T9: 0 | V9: 23 | X9: =P9+T9 -> 2246 | Y9: =Q9+U9 -> 0 | Z9: =R9+V9 -> 315 | AA9: =S9+W9 -> 0 | AB9: =L9+X9 -> 33158 | AC9: =M9+Y9 -> 0 | AD9: =N9+Z9 -> 33757 | AE9: =O9+AA9 -> 0 | AF9: 499392 | AH9: 0 | AJ9: 260558 | AL9: 9765 | AN9: 0 | AP9: 0 | AR9: =AH9+AJ9+AL9+AN9+AP9 -> 270323 | AS9: =AI9+AK9+AM9+AO9+AQ9 -> 0 | AT9: 757675 | AV9: 0 | AX9: 0 | AZ9: 0 | BB9: 10 | BD9: 5 | BF9: 0 | BH9: 0 | BJ9: 0 | BL9: =AV9+AX9+AZ9+BB9+BD9+BF9+BH9+BJ9 -> 15 | BM9: =AW9+AY9+BA9+BC9+BE9+BG9+BI9+BK9 -> 0 | BN9: =AX9+AZ9+BB9+BD9+BF9+BH9+BJ9+BL9 -> 30 | BO9: =AY9+BA9+BC9+BE9+BG9+BI9+BK9+BM9 -> 0 | BP9: 10901 | BR9: 8366 | BT9: =BP9+BR9 -> 19267 | BU9: =BQ9+BS9 -> 0 | BV9: 33958 | BX9: 13774 | BZ9: 0 | CB9: 8103 | CD9: 3283 | CF9: 502 | CH9: 0 | CJ9: 53 | CL9: =BV9+CD9 -> 37241 | CM9: =BW9+CE9 -> 0 | CN9: =BX9+CF9 -> 14276 | CO9: =BY9+CG9 -> 0 | CP9: =BZ9+CH9 -> 0 | CQ9: =CA9+CI9 -> 0 | CR9: =CB9+CJ9 -> 8156 | CS9: =CC9+CK9 -> 0 | CT9: =CL9+CP9 -> 37241 | CU9: =CM9+CQ9 -> 0 | CV9: =CN9+CR9 -> 22432 | CW9: =CO9+CS9 -> 0
B10: 716BD | C10: R&D | D10: 0 | F10: 0 | H10: 0 | J10: 0 | L10: =D10+H10 -> 0 | M10: =E10+I10 -> 0 | N10: =F10+J10 -> 0 | O10: =G10+K10 -> 0 | P10: 69 | R10: 4 | T10: 0 | V10: 0 | X10: =P10+T10 -> 69 | Y10: =Q10+U10 -> 0 | Z10: =R10+V10 -> 4 | AA10: =S10+W10 -> 0 | AB10: =L10+X10 -> 69 | AC10: =M10+Y10 -> 0 | AD10: =N10+Z10 -> 4 | AE10: =O10+AA10 -> 0 | AF10: 0 | AH10: 0 | AJ10: 0 | AL10: 0 | AN10: 0 | AP10: 0 | AR10: =AH10+AJ10+AL10+AN10+AP10 -> 0 | AS10: =AI10+AK10+AM10+AO10+AQ10 -> 0 | AT10: 0 | AV10: 0 | AX10: 0 | AZ10: 0 | BB10: 0 | BD10: 0 | BF10: 0 | BH10: 0 | BJ10: 0 | BL10: =AV10+AX10+AZ10+BB10+BD10+BF10+BH10+BJ10 -> 0 | BM10: =AW10+AY10+BA10+BC10+BE10+BG10+BI10+BK10 -> 0 | BN10: =AX10+AZ10+BB10+BD10+BF10+BH10+BJ10+BL10 -> 0 | BO10: =AY10+BA10+BC10+BE10+BG10+BI10+BK10+BM10 -> 0 | BP10: 0 | BR10: 0 | BT10: =BP10+BR10 -> 0 | BU10: =BQ10+BS10 -> 0 | BV10: 0 | BX10: 0 | BZ10: 0 | CB10: 0 | CD10: 69 | CF10: 4 | CH10: 0 | CJ10: 0 | CL10: =BV10+CD10 -> 69 | CM10: =BW10+CE10 -> 0 | CN10: =BX10+CF10 -> 4 | CO10: =BY10+CG10 -> 0 | CP10: =BZ10+CH10 -> 0 | CQ10: =CA10+CI10 -> 0 | CR10: =CB10+CJ10 -> 0 | CS10: =CC10+CK10 -> 0 | CT10: =CL10+CP10 -> 69 | CU10: =CM10+CQ10 -> 0 | CV10: =CN10+CR10 -> 4 | CW10: =CO10+CS10 -> 0
B11: 716CD | C11: R&D | D11: 0 | F11: 0 | H11: 0 | J11: 0 | L11: =D11+H11 -> 0 | M11: =E11+I11 -> 0 | N11: =F11+J11 -> 0 | O11: =G11+K11 -> 0 | P11: 0 | R11: 1 | T11: 0 | V11: 0 | X11: =P11+T11 -> 0 | Y11: =Q11+U11 -> 0 | Z11: =R11+V11 -> 1 | AA11: =S11+W11 -> 0 | AB11: =L11+X11 -> 0 | AC11: =M11+Y11 -> 0 | AD11: =N11+Z11 -> 1 | AE11: =O11+AA11 -> 0 | AF11: 0 | AH11: 0 | AJ11: 0 | AL11: 0 | AN11: 0 | AP11: 0 | AR11: =AH11+AJ11+AL11+AN11+AP11 -> 0 | AS11: =AI11+AK11+AM11+AO11+AQ11 -> 0 | AT11: 0 | AV11: 0 | AX11: 0 | AZ11: 0 | BB11: 0 | BD11: 0 | BF11: 0 | BH11: 0 | BJ11: 0 | BL11: =AV11+AX11+AZ11+BB11+BD11+BF11+BH11+BJ11 -> 0 | BM11: =AW11+AY11+BA11+BC11+BE11+BG11+BI11+BK11 -> 0 | BN11: =AX11+AZ11+BB11+BD11+BF11+BH11+BJ11+BL11 -> 0 | BO11: =AY11+BA11+BC11+BE11+BG11+BI11+BK11+BM11 -> 0 | BP11: 0 | BR11: 0 | BT11: =BP11+BR11 -> 0 | BU11: =BQ11+BS11 -> 0 | BV11: 0 | BX11: 0 | BZ11: 0 | CB11: 0 | CD11: 0 | CF11: 1 | CH11: 0 | CJ11: 0 | CL11: =BV11+CD11 -> 0 | CM11: =BW11+CE11 -> 0 | CN11: =BX11+CF11 -> 1 | CO11: =BY11+CG11 -> 0 | CP11: =BZ11+CH11 -> 0 | CQ11: =CA11+CI11 -> 0 | CR11: =CB11+CJ11 -> 0 | CS11: =CC11+CK11 -> 0 | CT11: =CL11+CP11 -> 0 | CU11: =CM11+CQ11 -> 0 | CV11: =CN11+CR11 -> 1 | CW11: =CO11+CS11 -> 0
B12: 716DD | C12: R&D | D12: 0 | F12: 0 | H12: 0 | J12: 0 | L12: =D12+H12 -> 0 | M12: =E12+I12 -> 0 | N12: =F12+J12 -> 0 | O12: =G12+K12 -> 0 | P12: 328 | R12: 2161 | T12: 0 | V12: 144 | X12: =P12+T12 -> 328 | Y12: =Q12+U12 -> 0 | Z12: =R12+V12 -> 2305 | AA12: =S12+W12 -> 0 | AB12: =L12+X12 -> 328 | AC12: =M12+Y12 -> 0 | AD12: =N12+Z12 -> 2305 | AE12: =O12+AA12 -> 0 | AF12: 0 | AH12: 0 | AJ12: 0 | AL12: 0 | AN12: 0 | AP12: 0 | AR12: =AH12+AJ12+AL12+AN12+AP12 -> 0 | AS12: =AI12+AK12+AM12+AO12+AQ12 -> 0 | AT12: 0 | AV12: 0 | AX12: 0 | AZ12: 0 | BB12: 0 | BD12: 0 | BF12: 0 | BH12: 0 | BJ12: 0 | BL12: =AV12+AX12+AZ12+BB12+BD12+BF12+BH12+BJ12 -> 0 | BM12: =AW12+AY12+BA12+BC12+BE12+BG12+BI12+BK12 -> 0 | BN12: =AX12+AZ12+BB12+BD12+BF12+BH12+BJ12+BL12 -> 0 | BO12: =AY12+BA12+BC12+BE12+BG12+BI12+BK12+BM12 -> 0 | BP12: 0 | BR12: 2295 | BT12: =BP12+BR12 -> 2295 | BU12: =BQ12+BS12 -> 0 | BV12: 0 | BX12: 0 | BZ12: 0 | CB12: 0 | CD12: 328 | CF12: 10 | CH12: 0 | CJ12: 0 | CL12: =BV12+CD12 -> 328 | CM12: =BW12+CE12 -> 0 | CN12: =BX12+CF12 -> 10 | CO12: =BY12+CG12 -> 0 | CP12: =BZ12+CH12 -> 0 | CQ12: =CA12+CI12 -> 0 | CR12: =CB12+CJ12 -> 0 | CS12: =CC12+CK12 -> 0 | CT12: =CL12+CP12 -> 328 | CU12: =CM12+CQ12 -> 0 | CV12: =CN12+CR12 -> 10 | CW12: =CO12+CS12 -> 0
B13: 716DTT | C13: R&D | D13: 0 | F13: 0 | H13: 0 | J13: 0 | L13: =D13+H13 -> 0 | M13: =E13+I13 -> 0 | N13: =F13+J13 -> 0 | O13: =G13+K13 -> 0 | P13: 320 | R13: 0 | T13: 0 | V13: 0 | X13: =P13+T13 -> 320 | Y13: =Q13+U13 -> 0 | Z13: =R13+V13 -> 0 | AA13: =S13+W13 -> 0 | AB13: =L13+X13 -> 320 | AC13: =M13+Y13 -> 0 | AD13: =N13+Z13 -> 0 | AE13: =O13+AA13 -> 0 | AF13: 16 | AH13: 0 | AJ13: 0 | AL13: 0 | AN13: 0 | AP13: 0 | AR13: =AH13+AJ13+AL13+AN13+AP13 -> 0 | AS13: =AI13+AK13+AM13+AO13+AQ13 -> 0 | AT13: 0 | AV13: 0 | AX13: 0 | AZ13: 0 | BB13: 0 | BD13: 300 | BF13: 0 | BH13: 0 | BJ13: 0 | BL13: =AV13+AX13+AZ13+BB13+BD13+BF13+BH13+BJ13 -> 300 | BM13: =AW13+AY13+BA13+BC13+BE13+BG13+BI13+BK13 -> 0 | BN13: =AX13+AZ13+BB13+BD13+BF13+BH13+BJ13+BL13 -> 600 | BO13: =AY13+BA13+BC13+BE13+BG13+BI13+BK13+BM13 -> 0 | BP13: 36 | BR13: 0 | BT13: =BP13+BR13 -> 36 | BU13: =BQ13+BS13 -> 0 | BV13: 0 | BX13: 0 | BZ13: 0 | CB13: 0 | CD13: 0 | CF13: 0 | CH13: 0 | CJ13: 0 | CL13: =BV13+CD13 -> 0 | CM13: =BW13+CE13 -> 0 | CN13: =BX13+CF13 -> 0 | CO13: =BY13+CG13 -> 0 | CP13: =BZ13+CH13 -> 0 | CQ13: =CA13+CI13 -> 0 | CR13: =CB13+CJ13 -> 0 | CS13: =CC13+CK13 -> 0 | CT13: =CL13+CP13 -> 0 | CU13: =CM13+CQ13 -> 0 | CV13: =CN13+CR13 -> 0 | CW13: =CO13+CS13 -> 0
B14: 716ED | C14: R&D | D14: 0 | F14: 0 | H14: 0 | J14: 0 | L14: =D14+H14 -> 0 | M14: =E14+I14 -> 0 | N14: =F14+J14 -> 0 | O14: =G14+K14 -> 0 | P14: 31 | R14: 1 | T14: 0 | V14: 0 | X14: =P14+T14 -> 31 | Y14: =Q14+U14 -> 0 | Z14: =R14+V14 -> 1 | AA14: =S14+W14 -> 0 | AB14: =L14+X14 -> 31 | AC14: =M14+Y14 -> 0 | AD14: =N14+Z14 -> 1 | AE14: =O14+AA14 -> 0 | AF14: 0 | AH14: 0 | AJ14: 0 | AL14: 0 | AN14: 0 | AP14: 0 | AR14: =AH14+AJ14+AL14+AN14+AP14 -> 0 | AS14: =AI14+AK14+AM14+AO14+AQ14 -> 0 | AT14: 0 | AV14: 0 | AX14: 0 | AZ14: 0 | BB14: 0 | BD14: 0 | BF14: 0 | BH14: 0 | BJ14: 0 | BL14: =AV14+AX14+AZ14+BB14+BD14+BF14+BH14+BJ14 -> 0 | BM14: =AW14+AY14+BA14+BC14+BE14+BG14+BI14+BK14 -> 0 | BN14: =AX14+AZ14+BB14+BD14+BF14+BH14+BJ14+BL14 -> 0 | BO14: =AY14+BA14+BC14+BE14+BG14+BI14+BK14+BM14 -> 0 | BP14: 0 | BR14: 0 | BT14: =BP14+BR14 -> 0 | BU14: =BQ14+BS14 -> 0 | BV14: 0 | BX14: 0 | BZ14: 0 | CB14: 0 | CD14: 31 | CF14: 1 | CH14: 0 | CJ14: 0 | CL14: =BV14+CD14 -> 31 | CM14: =BW14+CE14 -> 0 | CN14: =BX14+CF14 -> 1 | CO14: =BY14+CG14 -> 0 | CP14: =BZ14+CH14 -> 0 | CQ14: =CA14+CI14 -> 0 | CR14: =CB14+CJ14 -> 0 | CS14: =CC14+CK14 -> 0 | CT14: =CL14+CP14 -> 31 | CU14: =CM14+CQ14 -> 0 | CV14: =CN14+CR14 -> 1 | CW14: =CO14+CS14 -> 0
B15: 716ETT | C15: R&D | D15: 0 | F15: 0 | H15: 0 | J15: 0 | L15: =D15+H15 -> 0 | M15: =E15+I15 -> 0 | N15: =F15+J15 -> 0 | O15: =G15+K15 -> 0 | P15: 576 | R15: 0 | T15: 0 | V15: 0 | X15: =P15+T15 -> 576 | Y15: =Q15+U15 -> 0 | Z15: =R15+V15 -> 0 | AA15: =S15+W15 -> 0 | AB15: =L15+X15 -> 576 | AC15: =M15+Y15 -> 0 | AD15: =N15+Z15 -> 0 | AE15: =O15+AA15 -> 0 | AF15: 256 | AH15: 0 | AJ15: 0 | AL15: 0 | AN15: 0 | AP15: 0 | AR15: =AH15+AJ15+AL15+AN15+AP15 -> 0 | AS15: =AI15+AK15+AM15+AO15+AQ15 -> 0 | AT15: 0 | AV15: 0 | AX15: 0 | AZ15: 350 | BB15: 0 | BD15: 0 | BF15: 0 | BH15: 0 | BJ15: 0 | BL15: =AV15+AX15+AZ15+BB15+BD15+BF15+BH15+BJ15 -> 350 | BM15: =AW15+AY15+BA15+BC15+BE15+BG15+BI15+BK15 -> 0 | BN15: =AX15+AZ15+BB15+BD15+BF15+BH15+BJ15+BL15 -> 700 | BO15: =AY15+BA15+BC15+BE15+BG15+BI15+BK15+BM15 -> 0 | BP15: 418 | BR15: 0 | BT15: =BP15+BR15 -> 418 | BU15: =BQ15+BS15 -> 0 | BV15: 0 | BX15: 0 | BZ15: 0 | CB15: 0 | CD15: 64 | CF15: 0 | CH15: 0 | CJ15: 0 | CL15: =BV15+CD15 -> 64 | CM15: =BW15+CE15 -> 0 | CN15: =BX15+CF15 -> 0 | CO15: =BY15+CG15 -> 0 | CP15: =BZ15+CH15 -> 0 | CQ15: =CA15+CI15 -> 0 | CR15: =CB15+CJ15 -> 0 | CS15: =CC15+CK15 -> 0 | CT15: =CL15+CP15 -> 64 | CU15: =CM15+CQ15 -> 0 | CV15: =CN15+CR15 -> 0 | CW15: =CO15+CS15 -> 0
B16: 716FD | C16: R&D | D16: 0 | F16: 0 | H16: 0 | J16: 0 | L16: =D16+H16 -> 0 | M16: =E16+I16 -> 0 | N16: =F16+J16 -> 0 | O16: =G16+K16 -> 0 | P16: 67 | R16: 1 | T16: 0 | V16: 0 | X16: =P16+T16 -> 67 | Y16: =Q16+U16 -> 0 | Z16: =R16+V16 -> 1 | AA16: =S16+W16 -> 0 | AB16: =L16+X16 -> 67 | AC16: =M16+Y16 -> 0 | AD16: =N16+Z16 -> 1 | AE16: =O16+AA16 -> 0 | AF16: 0 | AH16: 0 | AJ16: 0 | AL16: 0 | AN16: 0 | AP16: 0 | AR16: =AH16+AJ16+AL16+AN16+AP16 -> 0 | AS16: =AI16+AK16+AM16+AO16+AQ16 -> 0 | AT16: 0 | AV16: 0 | AX16: 0 | AZ16: 0 | BB16: 0 | BD16: 0 | BF16: 0 | BH16: 0 | BJ16: 0 | BL16: =AV16+AX16+AZ16+BB16+BD16+BF16+BH16+BJ16 -> 0 | BM16: =AW16+AY16+BA16+BC16+BE16+BG16+BI16+BK16 -> 0 | BN16: =AX16+AZ16+BB16+BD16+BF16+BH16+BJ16+BL16 -> 0 | BO16: =AY16+BA16+BC16+BE16+BG16+BI16+BK16+BM16 -> 0 | BP16: 0 | BR16: 0 | BT16: =BP16+BR16 -> 0 | BU16: =BQ16+BS16 -> 0 | BV16: 0 | BX16: 0 | BZ16: 0 | CB16: 0 | CD16: 67 | CF16: 1 | CH16: 0 | CJ16: 0 | CL16: =BV16+CD16 -> 67 | CM16: =BW16+CE16 -> 0 | CN16: =BX16+CF16 -> 1 | CO16: =BY16+CG16 -> 0 | CP16: =BZ16+CH16 -> 0 | CQ16: =CA16+CI16 -> 0 | CR16: =CB16+CJ16 -> 0 | CS16: =CC16+CK16 -> 0 | CT16: =CL16+CP16 -> 67 | CU16: =CM16+CQ16 -> 0 | CV16: =CN16+CR16 -> 1 | CW16: =CO16+CS16 -> 0
B17: 716GD | C17: R&D | D17: 0 | F17: 0 | H17: 0 | J17: 0 | L17: =D17+H17 -> 0 | M17: =E17+I17 -> 0 | N17: =F17+J17 -> 0 | O17: =G17+K17 -> 0 | P17: 2 | R17: 1 | T17: 0 | V17: 0 | X17: =P17+T17 -> 2 | Y17: =Q17+U17 -> 0 | Z17: =R17+V17 -> 1 | AA17: =S17+W17 -> 0 | AB17: =L17+X17 -> 2 | AC17: =M17+Y17 -> 0 | AD17: =N17+Z17 -> 1 | AE17: =O17+AA17 -> 0 | AF17: 0 | AH17: 0 | AJ17: 0 | AL17: 0 | AN17: 0 | AP17: 0 | AR17: =AH17+AJ17+AL17+AN17+AP17 -> 0 | AS17: =AI17+AK17+AM17+AO17+AQ17 -> 0 | AT17: 0 | AV17: 0 | AX17: 0 | AZ17: 0 | BB17: 0 | BD17: 0 | BF17: 0 | BH17: 0 | BJ17: 0 | BL17: =AV17+AX17+AZ17+BB17+BD17+BF17+BH17+BJ17 -> 0 | BM17: =AW17+AY17+BA17+BC17+BE17+BG17+BI17+BK17 -> 0 | BN17: =AX17+AZ17+BB17+BD17+BF17+BH17+BJ17+BL17 -> 0 | BO17: =AY17+BA17+BC17+BE17+BG17+BI17+BK17+BM17 -> 0 | BP17: 0 | BR17: 0 | BT17: =BP17+BR17 -> 0 | BU17: =BQ17+BS17 -> 0 | BV17: 0 | BX17: 0 | BZ17: 0 | CB17: 0 | CD17: 2 | CF17: 1 | CH17: 0 | CJ17: 0 | CL17: =BV17+CD17 -> 2 | CM17: =BW17+CE17 -> 0 | CN17: =BX17+CF17 -> 1 | CO17: =BY17+CG17 -> 0 | CP17: =BZ17+CH17 -> 0 | CQ17: =CA17+CI17 -> 0 | CR17: =CB17+CJ17 -> 0 | CS17: =CC17+CK17 -> 0 | CT17: =CL17+CP17 -> 2 | CU17: =CM17+CQ17 -> 0 | CV17: =CN17+CR17 -> 1 | CW17: =CO17+CS17 -> 0
B18: 716JD | C18: R&D | D18: 0 | F18: 0 | H18: 0 | J18: 0 | L18: =D18+H18 -> 0 | M18: =E18+I18 -> 0 | N18: =F18+J18 -> 0 | O18: =G18+K18 -> 0 | P18: 15 | R18: 1 | T18: 0 | V18: 0 | X18: =P18+T18 -> 15 | Y18: =Q18+U18 -> 0 | Z18: =R18+V18 -> 1 | AA18: =S18+W18 -> 0 | AB18: =L18+X18 -> 15 | AC18: =M18+Y18 -> 0 | AD18: =N18+Z18 -> 1 | AE18: =O18+AA18 -> 0 | AF18: 0 | AH18: 0 | AJ18: 0 | AL18: 0 | AN18: 0 | AP18: 0 | AR18: =AH18+AJ18+AL18+AN18+AP18 -> 0 | AS18: =AI18+AK18+AM18+AO18+AQ18 -> 0 | AT18: 0 | AV18: 0 | AX18: 0 | AZ18: 0 | BB18: 0 | BD18: 0 | BF18: 0 | BH18: 0 | BJ18: 0 | BL18: =AV18+AX18+AZ18+BB18+BD18+BF18+BH18+BJ18 -> 0 | BM18: =AW18+AY18+BA18+BC18+BE18+BG18+BI18+BK18 -> 0 | BN18: =AX18+AZ18+BB18+BD18+BF18+BH18+BJ18+BL18 -> 0 | BO18: =AY18+BA18+BC18+BE18+BG18+BI18+BK18+BM18 -> 0 | BP18: 0 | BR18: 0 | BT18: =BP18+BR18 -> 0 | BU18: =BQ18+BS18 -> 0 | BV18: 0 | BX18: 0 | BZ18: 0 | CB18: 0 | CD18: 15 | CF18: 1 | CH18: 0 | CJ18: 0 | CL18: =BV18+CD18 -> 15 | CM18: =BW18+CE18 -> 0 | CN18: =BX18+CF18 -> 1 | CO18: =BY18+CG18 -> 0 | CP18: =BZ18+CH18 -> 0 | CQ18: =CA18+CI18 -> 0 | CR18: =CB18+CJ18 -> 0 | CS18: =CC18+CK18 -> 0 | CT18: =CL18+CP18 -> 15 | CU18: =CM18+CQ18 -> 0 | CV18: =CN18+CR18 -> 1 | CW18: =CO18+CS18 -> 0
... B78: 8191D | C78: R&D | D78: 0 | F78: 0 | H78: 0 | J78: 0 | L78: =D78+H78 -> 0 | M78: =E78+I78 -> 0 | N78: =F78+J78 -> 0 | O78: =G78+K78 -> 0 | P78: 30 | R78: 1 | T78: 0 | V78: 0 | X78: =P78+T78 -> 30 | Y78: =Q78+U78 -> 0 | Z78: =R78+V78 -> 1 | AA78: =S78+W78 -> 0 | AB78: =L78+X78 -> 30 | AC78: =M78+Y78 -> 0 | AD78: =N78+Z78 -> 1 | AE78: =O78+AA78 -> 0 | AF78: 0 | AH78: 0 | AJ78: 0 | AL78: 0 | AN78: 0 | AP78: 0 | AR78: =AH78+AJ78+AL78+AN78+AP78 -> 0 | AS78: =AI78+AK78+AM78+AO78+AQ78 -> 0 | AT78: 0 | AV78: 0 | AX78: 0 | AZ78: 0 | BB78: 0 | BD78: 0 | BF78: 0 | BH78: 0 | BJ78: 0 | BL78: =AV78+AX78+AZ78+BB78+BD78+BF78+BH78+BJ78 -> 0 | BM78: =AW78+AY78+BA78+BC78+BE78+BG78+BI78+BK78 -> 0 | BN78: =AX78+AZ78+BB78+BD78+BF78+BH78+BJ78+BL78 -> 0 | BO78: =AY78+BA78+BC78+BE78+BG78+BI78+BK78+BM78 -> 0 | BP78: 0 | BR78: 0 | BT78: =BP78+BR78 -> 0 | BU78: =BQ78+BS78 -> 0 | BV78: 0 | BX78: 0 | BZ78: 0 | CB78: 0 | CD78: 30 | CF78: 1 | CH78: 0 | CJ78: 0 | CL78: =BV78+CD78 -> 30 | CM78: =BW78+CE78 -> 0 | CN78: =BX78+CF78 -> 1 | CO78: =BY78+CG78 -> 0 | CP78: =BZ78+CH78 -> 0 | CQ78: =CA78+CI78 -> 0 | CR78: =CB78+CJ78 -> 0 | CS78: =CC78+CK78 -> 0 | CT78: =CL78+CP78 -> 30 | CU78: =CM78+CQ78 -> 0 | CV78: =CN78+CR78 -> 1 | CW78: =CO78+CS78 -> 0
B79: TOTAL | D79: =SUM(D7:D78) -> 36254 | E79: =SUM(E7:E78) -> 0 | F79: =SUM(F7:F78) -> 20177 | G79: =SUM(G7:G78) -> 0 | H79: =SUM(H7:H78) -> 0 | I79: =SUM(I7:I78) -> 0 | J79: =SUM(J7:J78) -> 15624 | K79: =SUM(K7:K78) -> 0 | ... AH79: =SUM(AH7:AH78) -> 0 | AJ79: =SUM(AJ7:AJ78) -> 276489 | AL79: =SUM(AL7:AL78) -> 9997 | AN79: =SUM(AN7:AN78) -> 0 | AP79: =SUM(AP7:AP78) -> 0 | AR79: =SUM(AR7:AR78) -> 286486 | AS79: =SUM(AS7:AS78) -> 0 | AT79: =SUM(AT7:AT78) -> 989673 | AU79: =SUM(AU7:AU78) -> 0 | AV79: =SUM(AV7:AV78) -> 0 | AW79: =SUM(AW7:AW78) -> 0 | AZ79: =SUM(AZ7:AZ78) -> 503 | BA79: =SUM(BA7:BA78) -> 0 | BD79: =SUM(BD7:BD78) -> 363 | BE79: =SUM(BE7:BE78) -> 0 | BH79: =SUM(BH7:BH78) -> 0 | BI79: =SUM(BI7:BI78) -> 0 | BL79: =SUM(BL7:BL78) -> 892 | BM79: =SUM(BM7:BM78) -> 0 | BN79: =SUM(BN7:BN78) -> 1784 | BO79: =SUM(BO7:BO78) -> 0 | BP79: =SUM(BP7:BP78) -> 22357 | BQ79: =SUM(BQ7:BQ78) -> 0 | BV79: =SUM(BV7:BV78) -> 65190 | BW79: =SUM(BW7:BW78) -> 0 | BX79: =SUM(BX7:BX78) -> 19319 | BY79: =SUM(BY7:BY78) -> 0 | BZ79: =SUM(BZ7:BZ78) -> 0 | CA79: =SUM(CA7:CA78) -> 0 | CB79: =SUM(CB7:CB78) -> 8377 | CC79: =SUM(CC7:CC78) -> 0 | ... CW79: =SUM(CW7:CW78) -> 0

Sheet 제품(TP) (매출원가_제품)
V1: 열고 닫는 기능 추가 필요 (좌측으로) | AF1: 열고 닫는 기능 추가 필요 (좌측으로) | AL1: 열고 닫는 기능 추가 필요 (좌측으로) | AV1: 열고 닫는 기능 추가 필요 (좌측으로)
B2: 모델 Model | C2: 구분 Division | D2: BOH | F2: INPUT | X2: 기타입고 | AH2: OUTPUT | AN2: 기타출고 | AX2: LOSS | AZ2: EOH WH0006
F3: 1 | H3: 2 | J3: 3 | L3: 4 | N3: 5 | P3: 6 | R3: 7 | T3: 8 | V3: 9=1+…+8 | X3: 1 | Z3: 2 | AB3: 3 | AD3: 4 | AF3: 5=1+2+3+4 | AH3: 1 | AJ3: 2 | AL3: 3=1+2 | AN3: 1 | AP3: 2 | AR3: 3 | AT3: 4 | AV3: 6=1+2+3+4
F4: NORMAL FG INPUT | J4: RW FROM LINE → FG-WAREHOUSE / REWORK 생산라인 → 완제품 창고 CELL 입고 | V4: T_INPUT | X4: RMA | Z4: 반제품 (유상) | AB4: 반제품 (무상) | AD4: 기타 | AF4: 기타입고 | AH4: SHIP (A 급) | AJ4: SHIP (B 급) | AL4: T_OUTPUT | AN4: Re-Sorting (재검사) | AP4: Re-work (SI검사) | AR4: 무상매출 | AT4: 기타 | AV4: 기타출고
F5: LAST-MONTH | H5: THIS-MONTH | J5: BACK-SHIP (SORTING) | L5: BACK-SHIP (PF-RW) | N5: BACK-SHIP (PL-RW) | P5: WH RETURN (SORTING) | R5: WH RETURN (PF-RW) | T5: WH RETURN (PL-RW) | AH5: PAID | AJ5: PAID | BC5: 검증
D6: 수량 | E6: 금액 | F6: 수량 | G6: 금액 | H6: 수량 | I6: 금액 | J6: 수량 | K6: 금액 | L6: 수량 | M6: 금액 | N6: 수량 | O6: 금액 | P6: 수량 | Q6: 금액 | R6: 수량 | S6: 금액 | T6: 수량 | U6: 금액 | V6: 수량 | W6: 금액 | X6: 수량 | Y6: 금액 | Z6: 수량 | AA6: 금액 | AB6: 수량 | AC6: 금액 | AD6: 수량 | AE6: 금액 | AF6: 수량 | AG6: 금액 | AH6: 수량 | AI6: 금액 | AJ6: 수량 | AK6: 금액 | AL6: 수량 | AM6: 금액 | AN6: 수량 | AO6: 금액 | AP6: 수량 | AQ6: 금액 | AR6: 수량 | AS6: 금액 | AT6: 수량 | AU6: 금액 | AV6: 수량 | AW6: 금액 | AX6: 수량 | AY6: 금액 | AZ6: 수량 | BA6: 금액
B7: 7075P | C7: =VLOOKUP(B7,'재공품 (WIP)_생산실적'!$B$6:$C$88,2,FALSE) -> MP | D7: =IFERROR(VLOOKUP(B7,'(A) Inventory'!$A$7:$C$89,3,0),0) -> 10030 | E7: 122436.31 | F7: =IFERROR(VLOOKUP(B7,'(B) FGs'!$B$6:$D$55,3,0),0) -> 0 | H7: =IFERROR(VLOOKUP(B7,'(B) FGs'!$B$6:$E$55,4,0),0) -> 0 | J7: =IFERROR(VLOOKUP(B7,'(B) FGs'!$B$6:$G$55,6,0),0) -> 0 | L7: =IFERROR(VLOOKUP(B7,'(B) FGs'!$B$6:$H$55,7,0),0) -> 0 | N7: =IFERROR(VLOOKUP(B7,'(B) FGs'!$B$6:$I$55,8,0),0) -> 0 | P7: =IFERROR(VLOOKUP(B7,'(B) FGs'!$B$6:$J$55,9,0),0) -> 0 | R7: =IFERROR(VLOOKUP(B7,'(B) FGs'!$B$6:$K$55,10,0),0) -> 0 | T7: =IFERROR(VLOOKUP(B7,'(B) FGs'!$B$6:$L$55,11,0),0) -> 0 | V7: =F7+H7+J7+L7+N7+P7+R7+T7 -> 0 | W7: =G7+I7+K7+M7+O7+Q7+S7+U7 -> 0 | X7: =IFERROR(VLOOKUP(B7,'(B) FGs'!$B$6:$R$55,13,0),0) -> 0 | Z7: =IFERROR(VLOOKUP(B7,'(A) Inventory'!$A$7:$R$89,18,0),0) -> 0 | AB7: =IFERROR(VLOOKUP(B7,'(A) Inventory'!$A$7:$S$89,19,0),0) -> 0 | AD7: 0 | AF7: =X7+Z7+AB7+AD7 -> 0 | AG7: =Y7+AA7+AC7+AE7 -> 0 | AH7: =IFERROR(VLOOKUP(B7,'(A) Inventory'!$A$7:$P$89,16,0),0) -> 0 | AJ7: =IFERROR(VLOOKUP(B7,'(A) Inventory'!$A$7:$R$89,18,0),0) -> 0 | AL7: =AH7+AJ7 -> 0 | AM7: =AI7+AK7 -> 0 | AN7: =IFERROR(VLOOKUP(B7,'(B) FGs'!$B$6:$S$55,18,0),0)-IFERROR(VLOOKUP(B7,'(B) FGs'!$B$6:$M$55,12,0),0) -> 0 | AP7: =IFERROR(VLOOKUP(B7,'(B) FGs'!$B$6:$M$55,12,0),0) -> 0 | AR7: =IFERROR(VLOOKUP(B7,'(A) Inventory'!$A$7:$S$89,19,0),0) -> 0 | AT7: 0 | AV7: =AN7+AP7+AR7+AT7 -> 0 | AW7: =AO7+AQ7+AS7+AU7 -> 0 | AX7: 0 | AZ7: =D7+V7+AF7-AL7-AV7-AX7 -> 10030 | BA7: =E7+W7+AG7-AM7-AW7-AY7 -> 122436.31 | BC7: =D7+V7+AF7-AL7-AV7-AX7=AZ7 -> TRUE | BD7: =D7+V7+AF7-AL7-AV7-AX7-AZ7 -> 0
B8: 712TP | C8: =VLOOKUP(B8,'재공품 (WIP)_생산실적'!$B$6:$C$88,2,FALSE) -> MP | D8: =IFERROR(VLOOKUP(B8,'(A) Inventory'!$A$7:$C$89,3,0),0) -> 0 | E8: 0 | F8: =IFERROR(VLOOKUP(B8,'(B) FGs'!$B$6:$D$55,3,0),0) -> 0 | H8: =IFERROR(VLOOKUP(B8,'(B) FGs'!$B$6:$E$55,4,0),0) -> 0 | J8: =IFERROR(VLOOKUP(B8,'(B) FGs'!$B$6:$G$55,6,0),0) -> 0 | L8: =IFERROR(VLOOKUP(B8,'(B) FGs'!$B$6:$H$55,7,0),0) -> 0 | N8: =IFERROR(VLOOKUP(B8,'(B) FGs'!$B$6:$I$55,8,0),0) -> 0 | P8: =IFERROR(VLOOKUP(B8,'(B) FGs'!$B$6:$J$55,9,0),0) -> 0 | R8: 0 | T8: =IFERROR(VLOOKUP(B8,'(B) FGs'!$B$6:$L$55,11,0),0) -> 0 | V8: =F8+H8+J8+L8+N8+P8+R8+T8 -> 0 | W8: =G8+I8+K8+M8+O8+Q8+S8+U8 -> 0 | X8: =IFERROR(VLOOKUP(B8,'(B) FGs'!$B$6:$R$55,13,0),0) -> 0 | Z8: =IFERROR(VLOOKUP(B8,'(A) Inventory'!$A$7:$R$89,18,0),0) -> 0 | AB8: =IFERROR(VLOOKUP(B8,'(A) Inventory'!$A$7:$S$89,19,0),0) -> 0 | AD8: 0 | AF8: =X8+Z8+AB8+AD8 -> 0 | AG8: =Y8+AA8+AC8+AE8 -> 0 | AH8: =IFERROR(VLOOKUP(B8,'(A) Inventory'!$A$7:$P$89,16,0),0) -> 0 | AJ8: =IFERROR(VLOOKUP(B8,'(A) Inventory'!$A$7:$R$89,18,0),0) -> 0 | AL8: =AH8+AJ8 -> 0 | AM8: =AI8+AK8 -> 0 | AN8: =IFERROR(VLOOKUP(B8,'(B) FGs'!$B$6:$S$55,18,0),0)-IFERROR(VLOOKUP(B8,'(B) FGs'!$B$6:$M$55,12,0),0) -> 0 | AP8: =IFERROR(VLOOKUP(B8,'(B) FGs'!$B$6:$M$55,12,0),0) -> 0 | AR8: =IFERROR(VLOOKUP(B8,'(A) Inventory'!$A$7:$S$89,19,0),0) -> 0 | AT8: 0 | AV8: =AN8+AP8+AR8+AT8 -> 0 | AW8: =AO8+AQ8+AS8+AU8 -> 0 | AX8: 0 | AZ8: =D8+V8+AF8-AL8-AV8-AX8 -> 0 | BA8: =E8+W8+AG8-AM8-AW8-AY8 -> 0 | BC8: =D8+V8+AF8-AL8-AV8-AX8=AZ8 -> TRUE | BD8: =D8+V8+AF8-AL8-AV8-AX8-AZ8 -> 0
B9: 716AP | C9: =VLOOKUP(B9,'재공품 (WIP)_생산실적'!$B$6:$C$88,2,FALSE) -> MP | D9: =IFERROR(VLOOKUP(B9,'(A) Inventory'!$A$7:$C$89,3,0),0) -> 387259 | E9: 4200575.1 | F9: =IFERROR(VLOOKUP(B9,'(B) FGs'!$B$6:$D$55,3,0),0) -> 39672 | H9: =IFERROR(VLOOKUP(B9,'(B) FGs'!$B$6:$E$55,4,0),0) -> 441648 | J9: =IFERROR(VLOOKUP(B9,'(B) FGs'!$B$6:$G$55,6,0),0) -> 23934 | L9: =IFERROR(VLOOKUP(B9,'(B) FGs'!$B$6:$H$55,7,0),0) -> 0 | N9: =IFERROR(VLOOKUP(B9,'(B) FGs'!$B$6:$I$55,8,0),0) -> 0 | P9: =IFERROR(VLOOKUP(B9,'(B) FGs'!$B$6:$J$55,9,0),0) -> 242656 | R9: 9765 | T9: =IFERROR(VLOOKUP(B9,'(B) FGs'!$B$6:$L$55,11,0),0) -> 0 | V9: =F9+H9+J9+L9+N9+P9+R9+T9 -> 757675 | W9: =G9+I9+K9+M9+O9+Q9+S9+U9 -> 0 | X9: =IFERROR(VLOOKUP(B9,'(B) FGs'!$B$6:$R$55,13,0),0) -> 0 | Z9: =IFERROR(VLOOKUP(B9,'(A) Inventory'!$A$7:$R$89,18,0),0) -> 10 | AB9: =IFERROR(VLOOKUP(B9,'(A) Inventory'!$A$7:$S$89,19,0),0) -> 5 | AD9: 0 | AF9: =X9+Z9+AB9+AD9 -> 15 | AG9: =Y9+AA9+AC9+AE9 -> 0 | AH9: =IFERROR(VLOOKUP(B9,'(A) Inventory'!$A$7:$P$89,16,0),0) -> 594080 | AJ9: =IFERROR(VLOOKUP(B9,'(A) Inventory'!$A$7:$R$89,18,0),0) -> 10 | AL9: =AH9+AJ9 -> 594090 | AM9: =AI9+AK9 -> 0 | AN9: =IFERROR(VLOOKUP(B9,'(B) FGs'!$B$6:$S$55,18,0),0)-IFERROR(VLOOKUP(B9,'(B) FGs'!$B$6:$M$55,12,0),0) -> 260558 | AP9: =IFERROR(VLOOKUP(B9,'(B) FGs'!$B$6:$M$55,12,0),0) -> 9765 | AR9: =IFERROR(VLOOKUP(B9,'(A) Inventory'!$A$7:$S$89,19,0),0) -> 5 | AT9: 0 | AV9: =AN9+AP9+AR9+AT9 -> 270328 | AW9: =AO9+AQ9+AS9+AU9 -> 0 | AX9: 0 | AZ9: =D9+V9+AF9-AL9-AV9-AX9 -> 280531 | BA9: =E9+W9+AG9-AM9-AW9-AY9 -> 4200575.1 | BC9: =D9+V9+AF9-AL9-AV9-AX9=AZ9 -> TRUE | BD9: =D9+V9+AF9-AL9-AV9-AX9-AZ9 -> 0
B10: 716BD | C10: =VLOOKUP(B10,'재공품 (WIP)_생산실적'!$B$6:$C$88,2,FALSE) -> R&D | D10: =IFERROR(VLOOKUP(B10,'(A) Inventory'!$A$7:$C$89,3,0),0) -> 987 | E10: 21037.24 | F10: =IFERROR(VLOOKUP(B10,'(B) FGs'!$B$6:$D$55,3,0),0) -> 0 | H10: =IFERROR(VLOOKUP(B10,'(B) FGs'!$B$6:$E$55,4,0),0) -> 0 | J10: =IFERROR(VLOOKUP(B10,'(B) FGs'!$B$6:$G$55,6,0),0) -> 0 | L10: =IFERROR(VLOOKUP(B10,'(B) FGs'!$B$6:$H$55,7,0),0) -> 0 | N10: =IFERROR(VLOOKUP(B10,'(B) FGs'!$B$6:$I$55,8,0),0) -> 0 | P10: =IFERROR(VLOOKUP(B10,'(B) FGs'!$B$6:$J$55,9,0),0) -> 0 | R10: 0 | T10: =IFERROR(VLOOKUP(B10,'(B) FGs'!$B$6:$L$55,11,0),0) -> 0 | V10: =F10+H10+J10+L10+N10+P10+R10+T10 -> 0 | W10: =G10+I10+K10+M10+O10+Q10+S10+U10 -> 0 | X10: =IFERROR(VLOOKUP(B10,'(B) FGs'!$B$6:$R$55,13,0),0) -> 0 | Z10: =IFERROR(VLOOKUP(B10,'(A) Inventory'!$A$7:$R$89,18,0),0) -> 0 | AB10: =IFERROR(VLOOKUP(B10,'(A) Inventory'!$A$7:$S$89,19,0),0) -> 0 | AD10: 0 | AF10: =X10+Z10+AB10+AD10 -> 0 | AG10: =Y10+AA10+AC10+AE10 -> 0 | AH10: =IFERROR(VLOOKUP(B10,'(A) Inventory'!$A$7:$P$89,16,0),0) -> 0 | AJ10: =IFERROR(VLOOKUP(B10,'(A) Inventory'!$A$7:$R$89,18,0),0) -> 0 | AL10: =AH10+AJ10 -> 0 | AM10: =AI10+AK10 -> 0 | AN10: =IFERROR(VLOOKUP(B10,'(B) FGs'!$B$6:$S$55,18,0),0)-IFERROR(VLOOKUP(B10,'(B) FGs'!$B$6:$M$55,12,0),0) -> 0 | AP10: =IFERROR(VLOOKUP(B10,'(B) FGs'!$B$6:$M$55,12,0),0) -> 0 | AR10: =IFERROR(VLOOKUP(B10,'(A) Inventory'!$A$7:$S$89,19,0),0) -> 0 | AT10: 0 | AV10: =AN10+AP10+AR10+AT10 -> 0 | AW10: =AO10+AQ10+AS10+AU10 -> 0 | AX10: 0 | AZ10: =D10+V10+AF10-AL10-AV10-AX10 -> 987 | BA10: =E10+W10+AG10-AM10-AW10-AY10 -> 21037.24 | BC10: =D10+V10+AF10-AL10-AV10-AX10=AZ10 -> TRUE | BD10: =D10+V10+AF10-AL10-AV10-AX10-AZ10 -> 0
